Workbook

Sheet TABELA AUXILIAR
A1: Grupo Solo | B1: Peso (kN/m³) | C1: Peso sub (kN/m³) | G1: Estacas - Propriedades geométricas
A2: Relleno (Aterro) | B2: 17 | C2: 10 | G2: Diameter (in) | H2: Diametro (m) | I2: Perímetro (m) | J2: Área (m²)
A3: Areias | B3: 18.5 | C3: 8.5 | G3: 48 | H3: =ROUNDDOWN(G3*0.0254,1) -> 1.2 | I3: =ROUNDDOWN(H3*PI(),2) -> 3.76 | J3: =ROUNDDOWN(PI()*(H3/2)^2,2) -> 1.13
A4: Gravas | B4: 20 | C4: 10.5 | G4: 54 | H4: =ROUNDDOWN(G4*0.0254,1) -> 1.3 | I4: =ROUNDDOWN(H4*PI(),2) -> 4.08 | J4: =ROUNDDOWN(PI()*(H4/2)^2,2) -> 1.32
A5: Finos | B5: 18 | C5: 11 | G5: 60 | H5: =ROUNDDOWN(G5*0.0254,1) -> 1.5 | I5: =ROUNDDOWN(H5*PI(),2) -> 4.71 | J5: =ROUNDDOWN(PI()*(H5/2)^2,2) -> 1.76
A9: Resumo
A10: Capacidade axial geotécnica da fase I | M10: 21400
A11: SPT | B11: Resistencia última (kN) | E11: Resistencia admissível (kN - FS=2) | H11: Profundidade necessária (m) | K11: Profundidade para capacidade fase I (m)
B12: 1.2 | C12: 1.3 | D12: 1.5 | E12: 1.2 | F12: 1.3 | G12: 1.5 | H12: 1.2 | I12: 1.3 | J12: 1.5 | K12: 1.2 | L12: 1.3 | M12: 1.5
A13: SPT-01 | B13: =MAX('SPT-01'!Q$2:Q$90) -> 45732.981 | C13: =MAX('SPT-01'!R$2:R$90) -> 49836.962 | D13: =MAX('SPT-01'!S$2:S$90) -> 58065.524 | E13: =MAX('SPT-01'!T$2:T$90) -> 22866 | F13: =MAX('SPT-01'!U$2:U$90) -> 24918 | G13: =MAX('SPT-01'!V$2:V$90) -> 29032 | H13: =_xlfn.XLOOKUP(B13,'SPT-01'!Q2:Q90,'SPT-01'!$B$2:$B$90,"",0,1) -> 53.4 | I13: =_xlfn.XLOOKUP(C13,'SPT-01'!R2:R90,'SPT-01'!$A$2:$A$90,"",0,1) -> 52.8 | J13: =_xlfn.XLOOKUP(D13,'SPT-01'!S2:S90,'SPT-01'!$A$2:$A$90,"",0,1) -> 52.8 | K13: {=_xlfn.XLOOKUP(TRUE, 'SPT-01'!T2:T90 > 'TABELA AUXILIAR'!$M$10, 'SPT-01'!$B$2:$B$90, "N/A", 0, 1)} -> 51 | L13: {=_xlfn.XLOOKUP(TRUE, 'SPT-01'!U2:U90 > 'TABELA AUXILIAR'!$M$10, 'SPT-01'!$B$2:$B$90, "N/A", 0, 1)} -> 47.4 | M13: {=_xlfn.XLOOKUP(TRUE, 'SPT-01'!V2:V90 > 'TABELA AUXILIAR'!$M$10, 'SPT-01'!$B$2:$B$90, "N/A", 0, 1)} -> 40.8
A14: SPT-02 | B14: =MAX('SPT-02'!Q$2:Q$90) -> 44068.724 | C14: =MAX('SPT-02'!R$2:R$90) -> 48133.913 | D14: =MAX('SPT-02'!S$2:S$90) -> 56358.374 | E14: =MAX('SPT-02'!T$2:T$90) -> 19832 | F14: =MAX('SPT-02'!U$2:U$90) -> 21669 | G14: =MAX('SPT-02'!V$2:V$90) -> 25392 | H14: =_xlfn.XLOOKUP(B14,'SPT-02'!Q3:Q91,'SPT-02'!$B$2:$B$90,"",0,1) -> 47.4 | I14: =_xlfn.XLOOKUP(C14,'SPT-02'!R3:R91,'SPT-02'!$A$2:$A$90,"",0,1) -> 46.8 | J14: =_xlfn.XLOOKUP(D14,'SPT-02'!S3:S91,'SPT-02'!$A$2:$A$90,"",0,1) -> 46.8 | K14: {=_xlfn.XLOOKUP(TRUE, 'SPT-02'!T3:T91 > 'TABELA AUXILIAR'!$M$10, 'SPT-02'!$B$2:$B$90, "N/A", 0, 1)} -> N/A | L14: {=_xlfn.XLOOKUP(TRUE, 'SPT-02'!U3:U91 > 'TABELA AUXILIAR'!$M$10, 'SPT-02'!$B$2:$B$90, "N/A", 0, 1)} -> 43.8 | M14: {=_xlfn.XLOOKUP(TRUE, 'SPT-02'!V3:V91 > 'TABELA AUXILIAR'!$M$10, 'SPT-02'!$B$2:$B$90, "N/A", 0, 1)} -> 39
A15: SPT-03 | B15: =MAX('SPT-03'!Q$2:Q$90) -> 42938.995 | C15: =MAX('SPT-03'!R$2:R$90) -> 46911.322 | D15: =MAX('SPT-03'!S$2:S$90) -> 54955.274 | E15: =MAX('SPT-03'!T$2:T$90) -> 19616 | F15: =MAX('SPT-03'!U$2:U$90) -> 21440 | G15: =MAX('SPT-03'!V$2:V$90) -> 25138 | H15: =_xlfn.XLOOKUP(B15,'SPT-03'!Q4:Q92,'SPT-03'!$B$2:$B$90,"",0,1) -> 46.2 | I15: =_xlfn.XLOOKUP(C15,'SPT-03'!R4:R92,'SPT-03'!$A$2:$A$90,"",0,1) -> 45.6 | J15: =_xlfn.XLOOKUP(D15,'SPT-03'!S4:S92,'SPT-03'!$A$2:$A$90,"",0,1) -> 45.6 | K15: {=_xlfn.XLOOKUP(TRUE, 'SPT-03'!T4:T92 > 'TABELA AUXILIAR'!$M$10, 'SPT-03'!$B$2:$B$90, "N/A", 0, 1)} -> N/A | L15: {=_xlfn.XLOOKUP(TRUE, 'SPT-03'!U4:U92 > 'TABELA AUXILIAR'!$M$10, 'SPT-03'!$B$2:$B$90, "N/A", 0, 1)} -> 43.2 | M15: {=_xlfn.XLOOKUP(TRUE, 'SPT-03'!V4:V92 > 'TABELA AUXILIAR'!$M$10, 'SPT-03'!$B$2:$B$90, "N/A", 0, 1)} -> 39
A16: SPT-04 | B16: =MAX('SPT-04'!Q$2:Q$90) -> 39884.844 | C16: =MAX('SPT-04'!R$2:R$90) -> 43594.583 | D16: =MAX('SPT-04'!S$2:S$90) -> 51119.693 | E16: =MAX('SPT-04'!T$2:T$90) -> 19193 | F16: =MAX('SPT-04'!U$2:U$90) -> 20981 | G16: =MAX('SPT-04'!V$2:V$90) -> 24611 | H16: =_xlfn.XLOOKUP(B16,'SPT-04'!Q5:Q93,'SPT-04'!$B$2:$B$90,"",0,1) -> 43.8 | I16: =_xlfn.XLOOKUP(C16,'SPT-04'!R5:R93,'SPT-04'!$A$2:$A$90,"",0,1) -> 43.2 | J16: =_xlfn.XLOOKUP(D16,'SPT-04'!S5:S93,'SPT-04'!$A$2:$A$90,"",0,1) -> 43.2 | K16: {=_xlfn.XLOOKUP(TRUE, 'SPT-04'!T5:T93 > 'TABELA AUXILIAR'!$M$10, 'SPT-04'!$B$2:$B$90, "N/A", 0, 1)} -> N/A | L16: {=_xlfn.XLOOKUP(TRUE, 'SPT-04'!U5:U93 > 'TABELA AUXILIAR'!$M$10, 'SPT-04'!$B$2:$B$90, "N/A", 0, 1)} -> N/A | M16: {=_xlfn.XLOOKUP(TRUE, 'SPT-04'!V5:V93 > 'TABELA AUXILIAR'!$M$10, 'SPT-04'!$B$2:$B$90, "N/A", 0, 1)} -> 39
A17: SPT-05 | B17: =MAX('SPT-05'!Q$2:Q$90) -> 37859.82 | C17: =MAX('SPT-05'!R$2:R$90) -> 41394.709 | D17: =MAX('SPT-05'!S$2:S$90) -> 48573.82 | E17: =MAX('SPT-05'!T$2:T$90) -> 18504 | F17: =MAX('SPT-05'!U$2:U$90) -> 20234 | G17: =MAX('SPT-05'!V$2:V$90) -> 23750 | H17: =_xlfn.XLOOKUP(B17,'SPT-05'!Q6:Q94,'SPT-05'!$B$2:$B$90,"",0,1) -> 42.6 | I17: =_xlfn.XLOOKUP(C17,'SPT-05'!R6:R94,'SPT-05'!$A$2:$A$90,"",0,1) -> 42 | J17: =_xlfn.XLOOKUP(D17,'SPT-05'!S6:S94,'SPT-05'!$A$2:$A$90,"",0,1) -> 42 | K17: {=_xlfn.XLOOKUP(TRUE, 'SPT-05'!T6:T94 > 'TABELA AUXILIAR'!$M$10, 'SPT-05'!$B$2:$B$90, "N/A", 0, 1)} -> N/A | L17: {=_xlfn.XLOOKUP(TRUE, 'SPT-05'!U6:U94 > 'TABELA AUXILIAR'!$M$10, 'SPT-05'!$B$2:$B$90, "N/A", 0, 1)} -> N/A | M17: {=_xlfn.XLOOKUP(TRUE, 'SPT-05'!V6:V94 > 'TABELA AUXILIAR'!$M$10, 'SPT-05'!$B$2:$B$90, "N/A", 0, 1)} -> 39.6
A18: SPT-06 | B18: =MAX('SPT-06'!Q$2:Q$90) -> 39752.389 | C18: =MAX('SPT-06'!R$2:R$90) -> 43447.236 | D18: =MAX('SPT-06'!S$2:S$90) -> 50940.482 | E18: =MAX('SPT-06'!T$2:T$90) -> 19169 | F18: =MAX('SPT-06'!U$2:U$90) -> 20954 | G18: =MAX('SPT-06'!V$2:V$90) -> 24577 | H18: =_xlfn.XLOOKUP(B18,'SPT-06'!Q7:Q95,'SPT-06'!$B$2:$B$90,"",0,1) -> 42.6 | I18: =_xlfn.XLOOKUP(C18,'SPT-06'!R7:R95,'SPT-06'!$A$2:$A$90,"",0,1) -> 42 | J18: =_xlfn.XLOOKUP(D18,'SPT-06'!S7:S95,'SPT-06'!$A$2:$A$90,"",0,1) -> 42 | K18: {=_xlfn.XLOOKUP(TRUE, 'SPT-06'!T7:T95 > 'TABELA AUXILIAR'!$M$10, 'SPT-06'!$B$2:$B$90, "N/A", 0, 1)} -> N/A | L18: {=_xlfn.XLOOKUP(TRUE, 'SPT-06'!U7:U95 > 'TABELA AUXILIAR'!$M$10, 'SPT-06'!$B$2:$B$90, "N/A", 0, 1)} -> N/A | M18: {=_xlfn.XLOOKUP(TRUE, 'SPT-06'!V7:V95 > 'TABELA AUXILIAR'!$M$10, 'SPT-06'!$B$2:$B$90, "N/A", 0, 1)} -> 37.8
A19: Médio - percentil 10% | B19: =MAX('SPT médio'!Q$2:Q$90) -> 35574.434 | C19: =MAX('SPT médio'!R$2:R$90) -> 38881.569 | D19: =MAX('SPT médio'!S$2:S$90) -> 45588.922 | E19: =MAX('SPT médio'!T$2:T$90) -> 17787.21 | F19: =MAX('SPT médio'!U$2:U$90) -> 19440.78 | G19: =MAX('SPT médio'!V$2:V$90) -> 22794.46 | H19: =_xlfn.XLOOKUP(B19,'SPT médio'!Q8:Q96,'SPT médio'!$B$2:$B$90,"",0,1) -> 40.8 | I19: =_xlfn.XLOOKUP(C19,'SPT médio'!R8:R96,'SPT médio'!$A$2:$A$90,"",0,1) -> 40.2 | J19: =_xlfn.XLOOKUP(D19,'SPT médio'!S8:S96,'SPT médio'!$A$2:$A$90,"",0,1) -> 40.2 | K19: {=_xlfn.XLOOKUP(TRUE, 'SPT médio'!T8:T96 > 'TABELA AUXILIAR'!$M$10, 'SPT médio'!$B$2:$B$90, "N/A", 0, 1)} -> N/A | L19: {=_xlfn.XLOOKUP(TRUE, 'SPT médio'!U8:U96 > 'TABELA AUXILIAR'!$M$10, 'SPT médio'!$B$2:$B$90, "N/A", 0, 1)} -> N/A | M19: {=_xlfn.XLOOKUP(TRUE, 'SPT médio'!V8:V96 > 'TABELA AUXILIAR'!$M$10, 'SPT médio'!$B$2:$B$90, "N/A", 0, 1)} -> 39

Sheet Capacidade por eixo
A1: Considerando o pior caso (SPT-01) | E1: 21400 | J1: Prof | K1: Rn-1,2m (kN) - A | L1: Rn-1,3m (kN) - A | M1: Rn-1,5m (kN) - A | N1: 34 | O1: Prof | P1: Rn-1,2m (kN) - B | Q1: Rn-1,3m (kN) - B | R1: Rn-1,5m (kN) - B | S1: 26 | T1: Prof | U1: Rn-1,2m (kN) - C | V1: Rn-1,3m (kN) - C | W1: Rn-1,5m (kN) - C | X1: 18 | Y1: Prof | Z1: Rn-1,2m (kN) - D | AA1: Rn-1,3m (kN) - D | AB1: Rn-1,5m (kN) - D | AC1: 10 | AD1: Prof | AE1: Rn-1,2m (kN) - E | AF1: Rn-1,3m (kN) - E | AG1: Rn-1,5m (kN) - E
A2: Eixo | B2: Cota TOPO | C2: 1,2m - cota de fundo | D2: 1,3m - cota de fundo | E2: 1,5m - cota de fundo | F2: Embutimento-1,2M | G2: Embutimento-1,3M | H2: Embutimento-1,5M | J2: 21 | K2: =ROUNDDOWN(('SPT-01'!$M37*'TABELA AUXILIAR'!$J$3+SUM('SPT-01'!$N$37:$N37))/2,0)*0.9 -> 1278 | L2: =ROUNDDOWN(('SPT-01'!$M37*'TABELA AUXILIAR'!$J$4+SUM('SPT-01'!$O$37:$O37))/2,0)*0.9 -> 1473.3 | M2: =ROUNDDOWN(('SPT-01'!$M37*'TABELA AUXILIAR'!$J$5+SUM('SPT-01'!$P$37:$P37))/2,0)*0.9 -> 1918.8 | O2: 19.2 | P2: =ROUNDDOWN(('SPT-01'!$M34*'TABELA AUXILIAR'!$J$3+SUM('SPT-01'!$N$34:$N34))/2,0)*0.9 -> 1353.6 | Q2: =ROUNDDOWN(('SPT-01'!$M34*'TABELA AUXILIAR'!$J$4+SUM('SPT-01'!$O$34:$O34))/2,0)*0.9 -> 1561.5 | R2: =ROUNDDOWN(('SPT-01'!$M34*'TABELA AUXILIAR'!$J$5+SUM('SPT-01'!$P$34:$P34))/2,0)*0.9 -> 2034 | T2: 14.4 | U2: =ROUNDDOWN(('SPT-01'!$M26*'TABELA AUXILIAR'!$J$3+SUM('SPT-01'!$N$26:$N26))/2,0)*0.9 -> 1145.7 | V2: =ROUNDDOWN(('SPT-01'!$M26*'TABELA AUXILIAR'!$J$4+SUM('SPT-01'!$O$26:$O26))/2,0)*0.9 -> 1323.9 | W2: =ROUNDDOWN(('SPT-01'!$M26*'TABELA AUXILIAR'!$J$5+SUM('SPT-01'!$P$26:$P26))/2,0)*0.9 -> 1731.6 | Y2: 9.6 | Z2: =ROUNDDOWN(('SPT-01'!$M18*'TABELA AUXILIAR'!$J$3+SUM('SPT-01'!$N$18:$N18))/2,0)*0.9 -> 767.7 | AA2: =ROUNDDOWN(('SPT-01'!$M18*'TABELA AUXILIAR'!$J$4+SUM('SPT-01'!$O$18:$O18))/2,0)*0.9 -> 886.5 | AB2: =ROUNDDOWN(('SPT-01'!$M18*'TABELA AUXILIAR'!$J$5+SUM('SPT-01'!$P$18:$P18))/2,0)*0.9 -> 1160.1 | AD2: 4.8 | AE2: =ROUNDDOWN(('SPT-01'!$M10*'TABELA AUXILIAR'!$J$3+SUM('SPT-01'!$N$10:$N10))/2,0)*0.9 -> 292.5 | AF2: =ROUNDDOWN(('SPT-01'!$M10*'TABELA AUXILIAR'!$J$4+SUM('SPT-01'!$O$10:$O10))/2,0)*0.9 -> 338.4 | AG2: =ROUNDDOWN(('SPT-01'!$M10*'TABELA AUXILIAR'!$J$5+SUM('SPT-01'!$P$10:$P10))/2,0)*0.9 -> 441.9
A3: A | B3: 20.75 | C3: {=_xlfn.XLOOKUP(TRUE, K$2:K$182 > $E$1, $J$2:$J$182, "N/A", 0, 1)} -> 63.6 | D3: {=_xlfn.XLOOKUP(TRUE, L$2:L$182 > $E$1, $J$2:$J$182, "N/A", 0, 1)} -> 60.6 | E3: {=_xlfn.XLOOKUP(TRUE, M$2:M$182 > $E$1, $J$2:$J$182, "N/A", 0, 1)} -> 55.2 | F3: =C3-$B3 -> 42.85 | G3: =D3-$B3 -> 39.85 | H3: =E3-$B3 -> 34.45 | J3: 21.6 | K3: =ROUNDDOWN(('SPT-01'!$M38*'TABELA AUXILIAR'!$J$3+SUM('SPT-01'!$N$37:$N38))/2,0)*0.9 -> 1662.3 | L3: =ROUNDDOWN(('SPT-01'!$M38*'TABELA AUXILIAR'!$J$4+SUM('SPT-01'!$O$37:$O38))/2,0)*0.9 -> 1901.7 | M3: =ROUNDDOWN(('SPT-01'!$M38*'TABELA AUXILIAR'!$J$5+SUM('SPT-01'!$P$37:$P38))/2,0)*0.9 -> 2439.9 | O3: 19.8 | P3: =ROUNDDOWN(('SPT-01'!$M35*'TABELA AUXILIAR'!$J$3+SUM('SPT-01'!$N$34:$N35))/2,0)*0.9 -> 1617.3 | Q3: =ROUNDDOWN(('SPT-01'!$M35*'TABELA AUXILIAR'!$J$4+SUM('SPT-01'!$O$34:$O35))/2,0)*0.9 -> 1848.6 | R3: =ROUNDDOWN(('SPT-01'!$M35*'TABELA AUXILIAR'!$J$5+SUM('SPT-01'!$P$34:$P35))/2,0)*0.9 -> 2368.8 | T3: 15 | U3: =ROUNDDOWN(('SPT-01'!$M27*'TABELA AUXILIAR'!$J$3+SUM('SPT-01'!$N$26:$N27))/2,0)*0.9 -> 977.4 | V3: =ROUNDDOWN(('SPT-01'!$M27*'TABELA AUXILIAR'!$J$4+SUM('SPT-01'!$O$26:$O27))/2,0)*0.9 -> 1116.9 | W3: =ROUNDDOWN(('SPT-01'!$M27*'TABELA AUXILIAR'!$J$5+SUM('SPT-01'!$P$26:$P27))/2,0)*0.9 -> 1430.1 | Y3: 10.2 | Z3: =ROUNDDOWN(('SPT-01'!$M19*'TABELA AUXILIAR'!$J$3+SUM('SPT-01'!$N$18:$N19))/2,0)*0.9 -> 1079.1 | AA3: =ROUNDDOWN(('SPT-01'!$M19*'TABELA AUXILIAR'!$J$4+SUM('SPT-01'!$O$18:$O19))/2,0)*0.9 -> 1238.4 | AB3: =ROUNDDOWN(('SPT-01'!$M19*'TABELA AUXILIAR'!$J$5+SUM('SPT-01'!$P$18:$P19))/2,0)*0.9 -> 1601.1 | AD3: 5.4 | AE3: =ROUNDDOWN(('SPT-01'!$M11*'TABELA AUXILIAR'!$J$3+SUM('SPT-01'!$N$10:$N11))/2,0)*0.9 -> 550.8 | AF3: =ROUNDDOWN(('SPT-01'!$M11*'TABELA AUXILIAR'!$J$4+SUM('SPT-01'!$O$10:$O11))/2,0)*0.9 -> 633.6 | AG3: =ROUNDDOWN(('SPT-01'!$M11*'TABELA AUXILIAR'!$J$5+SUM('SPT-01'!$P$10:$P11))/2,0)*0.9 -> 821.7
A4: B | B4: 19 | C4: {=_xlfn.XLOOKUP(TRUE, P$2:P$182 > $E$1, $O$2:$O$182, "N/A", 0, 1)} -> 62.4 | D4: {=_xlfn.XLOOKUP(TRUE, Q$2:Q$182 > $E$1, $O$2:$O$182, "N/A", 0, 1)} -> 58.8 | E4: {=_xlfn.XLOOKUP(TRUE, R$2:R$182 > $E$1, $O$2:$O$182, "N/A", 0, 1)} -> 53.4 | F4: =C4-$B4 -> 43.4 | G4: =D4-$B4 -> 39.8 | H4: =E4-$B4 -> 34.4 | J4: 22.2 | K4: =ROUNDDOWN(('SPT-01'!$M39*'TABELA AUXILIAR'!$J$3+SUM('SPT-01'!$N$37:$N39))/2,0)*0.9 -> 1938.6 | L4: =ROUNDDOWN(('SPT-01'!$M39*'TABELA AUXILIAR'!$J$4+SUM('SPT-01'!$O$37:$O39))/2,0)*0.9 -> 2201.4 | M4: =ROUNDDOWN(('SPT-01'!$M39*'TABELA AUXILIAR'!$J$5+SUM('SPT-01'!$P$37:$P39))/2,0)*0.9 -> 2789.1 | O4: 20.4 | P4: =ROUNDDOWN(('SPT-01'!$M36*'TABELA AUXILIAR'!$J$3+SUM('SPT-01'!$N$34:$N36))/2,0)*0.9 -> 1883.7 | Q4: =ROUNDDOWN(('SPT-01'!$M36*'TABELA AUXILIAR'!$J$4+SUM('SPT-01'!$O$34:$O36))/2,0)*0.9 -> 2138.4 | R4: =ROUNDDOWN(('SPT-01'!$M36*'TABELA AUXILIAR'!$J$5+SUM('SPT-01'!$P$34:$P36))/2,0)*0.9 -> 2707.2 | T4: 15.6 | U4: =ROUNDDOWN(('SPT-01'!$M28*'TABELA AUXILIAR'!$J$3+SUM('SPT-01'!$N$26:$N28))/2,0)*0.9 -> 1056.6 | V4: =ROUNDDOWN(('SPT-01'!$M28*'TABELA AUXILIAR'!$J$4+SUM('SPT-01'!$O$26:$O28))/2,0)*0.9 -> 1199.7 | W4: =ROUNDDOWN(('SPT-01'!$M28*'TABELA AUXILIAR'!$J$5+SUM('SPT-01'!$P$26:$P28))/2,0)*0.9 -> 1518.3 | Y4: 10.8 | Z4: =ROUNDDOWN(('SPT-01'!$M20*'TABELA AUXILIAR'!$J$3+SUM('SPT-01'!$N$18:$N20))/2,0)*0.9 -> 779.4 | AA4: =ROUNDDOWN(('SPT-01'!$M20*'TABELA AUXILIAR'!$J$4+SUM('SPT-01'!$O$18:$O20))/2,0)*0.9 -> 882 | AB4: =ROUNDDOWN(('SPT-01'!$M20*'TABELA AUXILIAR'!$J$5+SUM('SPT-01'!$P$18:$P20))/2,0)*0.9 -> 1108.8 | AD4: 6 | AE4: =ROUNDDOWN(('SPT-01'!$M12*'TABELA AUXILIAR'!$J$3+SUM('SPT-01'!$N$10:$N12))/2,0)*0.9 -> 874.8 | AF4: =ROUNDDOWN(('SPT-01'!$M12*'TABELA AUXILIAR'!$J$4+SUM('SPT-01'!$O$10:$O12))/2,0)*0.9 -> 1002.6 | AG4: =ROUNDDOWN(('SPT-01'!$M12*'TABELA AUXILIAR'!$J$5+SUM('SPT-01'!$P$10:$P12))/2,0)*0.9 -> 1291.5
A5: C | B5: 14.4 | C5: {=_xlfn.XLOOKUP(TRUE, U$2:U$182 > $E$1, $T$2:$T$182, "N/A", 0, 1)} -> 59.4 | D5: {=_xlfn.XLOOKUP(TRUE, V$2:V$182 > $E$1, $T$2:$T$182, "N/A", 0, 1)} -> 55.8 | E5: {=_xlfn.XLOOKUP(TRUE, W$2:W$182 > $E$1, $T$2:$T$182, "N/A", 0, 1)} -> 50.4 | F5: =C5-$B5 -> 45 | G5: =D5-$B5 -> 41.4 | H5: =E5-$B5 -> 36 | J5: 22.8 | K5: =ROUNDDOWN(('SPT-01'!$M40*'TABELA AUXILIAR'!$J$3+SUM('SPT-01'!$N$37:$N40))/2,0)*0.9 -> 2217.6 | L5: =ROUNDDOWN(('SPT-01'!$M40*'TABELA AUXILIAR'!$J$4+SUM('SPT-01'!$O$37:$O40))/2,0)*0.9 -> 2505.6 | M5: =ROUNDDOWN(('SPT-01'!$M40*'TABELA AUXILIAR'!$J$5+SUM('SPT-01'!$P$37:$P40))/2,0)*0.9 -> 3143.7 | O5: 21 | P5: =ROUNDDOWN(('SPT-01'!$M37*'TABELA AUXILIAR'!$J$3+SUM('SPT-01'!$N$34:$N37))/2,0)*0.9 -> 2021.4 | Q5: =ROUNDDOWN(('SPT-01'!$M37*'TABELA AUXILIAR'!$J$4+SUM('SPT-01'!$O$34:$O37))/2,0)*0.9 -> 2280.6 | R5: =ROUNDDOWN(('SPT-01'!$M37*'TABELA AUXILIAR'!$J$5+SUM('SPT-01'!$P$34:$P37))/2,0)*0.9 -> 2850.3 | T5: 16.2 | U5: =ROUNDDOWN(('SPT-01'!$M29*'TABELA AUXILIAR'!$J$3+SUM('SPT-01'!$N$26:$N29))/2,0)*0.9 -> 1678.5 | V5: =ROUNDDOWN(('SPT-01'!$M29*'TABELA AUXILIAR'!$J$4+SUM('SPT-01'!$O$26:$O29))/2,0)*0.9 -> 1907.1 | W5: =ROUNDDOWN(('SPT-01'!$M29*'TABELA AUXILIAR'!$J$5+SUM('SPT-01'!$P$26:$P29))/2,0)*0.9 -> 2417.4 | Y5: 11.4 | Z5: =ROUNDDOWN(('SPT-01'!$M21*'TABELA AUXILIAR'!$J$3+SUM('SPT-01'!$N$18:$N21))/2,0)*0.9 -> 1359.9 | AA5: =ROUNDDOWN(('SPT-01'!$M21*'TABELA AUXILIAR'!$J$4+SUM('SPT-01'!$O$18:$O21))/2,0)*0.9 -> 1548 | AB5: =ROUNDDOWN(('SPT-01'!$M21*'TABELA AUXILIAR'!$J$5+SUM('SPT-01'!$P$18:$P21))/2,0)*0.9 -> 1967.4 | AD5: 6.6 | AE5: =ROUNDDOWN(('SPT-01'!$M13*'TABELA AUXILIAR'!$J$3+SUM('SPT-01'!$N$10:$N13))/2,0)*0.9 -> 1017.9 | AF5: =ROUNDDOWN(('SPT-01'!$M13*'TABELA AUXILIAR'!$J$4+SUM('SPT-01'!$O$10:$O13))/2,0)*0.9 -> 1160.1 | AG5: =ROUNDDOWN(('SPT-01'!$M13*'TABELA AUXILIAR'!$J$5+SUM('SPT-01'!$P$10:$P13))/2,0)*0.9 -> 1478.7
A6: D | B6: 9.35 | C6: {=_xlfn.XLOOKUP(TRUE, Z$2:Z$182 > $E$1, $Y$2:$Y$182, "N/A", 0, 1)} -> 57 | D6: {=_xlfn.XLOOKUP(TRUE, AA$2:AA$182 > $E$1, $Y$2:$Y$182, "N/A", 0, 1)} -> 53.4 | E6: {=_xlfn.XLOOKUP(TRUE, AB$2:AB$182 > $E$1, $Y$2:$Y$182, "N/A", 0, 1)} -> 48 | F6: =C6-$B6 -> 47.65 | G6: =D6-$B6 -> 44.05 | H6: =E6-$B6 -> 38.65 | J6: 23.4 | K6: =ROUNDDOWN(('SPT-01'!$M41*'TABELA AUXILIAR'!$J$3+SUM('SPT-01'!$N$37:$N41))/2,0)*0.9 -> 2499.3 | L6: =ROUNDDOWN(('SPT-01'!$M41*'TABELA AUXILIAR'!$J$4+SUM('SPT-01'!$O$37:$O41))/2,0)*0.9 -> 2812.5 | M6: =ROUNDDOWN(('SPT-01'!$M41*'TABELA AUXILIAR'!$J$5+SUM('SPT-01'!$P$37:$P41))/2,0)*0.9 -> 3501 | O6: 21.6 | P6: =ROUNDDOWN(('SPT-01'!$M38*'TABELA AUXILIAR'!$J$3+SUM('SPT-01'!$N$34:$N38))/2,0)*0.9 -> 2406.6 | Q6: =ROUNDDOWN(('SPT-01'!$M38*'TABELA AUXILIAR'!$J$4+SUM('SPT-01'!$O$34:$O38))/2,0)*0.9 -> 2709 | R6: =ROUNDDOWN(('SPT-01'!$M38*'TABELA AUXILIAR'!$J$5+SUM('SPT-01'!$P$34:$P38))/2,0)*0.9 -> 3371.4 | T6: 16.8 | U6: =ROUNDDOWN(('SPT-01'!$M30*'TABELA AUXILIAR'!$J$3+SUM('SPT-01'!$N$26:$N30))/2,0)*0.9 -> 1926 | V6: =ROUNDDOWN(('SPT-01'!$M30*'TABELA AUXILIAR'!$J$4+SUM('SPT-01'!$O$26:$O30))/2,0)*0.9 -> 2176.2 | W6: =ROUNDDOWN(('SPT-01'!$M30*'TABELA AUXILIAR'!$J$5+SUM('SPT-01'!$P$26:$P30))/2,0)*0.9 -> 2731.5 | Y6: 12 | Z6: =ROUNDDOWN(('SPT-01'!$M22*'TABELA AUXILIAR'!$J$3+SUM('SPT-01'!$N$18:$N22))/2,0)*0.9 -> 1539.9 | AA6: =ROUNDDOWN(('SPT-01'!$M22*'TABELA AUXILIAR'!$J$4+SUM('SPT-01'!$O$18:$O22))/2,0)*0.9 -> 1745.1 | AB6: =ROUNDDOWN(('SPT-01'!$M22*'TABELA AUXILIAR'!$J$5+SUM('SPT-01'!$P$18:$P22))/2,0)*0.9 -> 2199.6 | AD6: 7.2 | AE6: =ROUNDDOWN(('SPT-01'!$M14*'TABELA AUXILIAR'!$J$3+SUM('SPT-01'!$N$10:$N14))/2,0)*0.9 -> 1059.3 | AF6: =ROUNDDOWN(('SPT-01'!$M14*'TABELA AUXILIAR'!$J$4+SUM('SPT-01'!$O$10:$O14))/2,0)*0.9 -> 1199.7 | AG6: =ROUNDDOWN(('SPT-01'!$M14*'TABELA AUXILIAR'!$J$5+SUM('SPT-01'!$P$10:$P14))/2,0)*0.9 -> 1511.1
A7: E | B7: 4.6 | C7: {=_xlfn.XLOOKUP(TRUE, AE$2:AE$182 > $E$1, $AD$2:$AD$182, "N/A", 0, 1)} -> 55.8 | D7: {=_xlfn.XLOOKUP(TRUE, AF$2:AF$182 > $E$1, $AD$2:$AD$182, "N/A", 0, 1)} -> 52.2 | E7: {=_xlfn.XLOOKUP(TRUE, AG$2:AG$182 > $E$1, $AD$2:$AD$182, "N/A", 0, 1)} -> 46.2 | F7: =C7-$B7 -> 51.2 | G7: =D7-$B7 -> 47.6 | H7: =E7-$B7 -> 41.6 | J7: 24 | K7: =ROUNDDOWN(('SPT-01'!$M42*'TABELA AUXILIAR'!$J$3+SUM('SPT-01'!$N$37:$N42))/2,0)*0.9 -> 2223 | L7: =ROUNDDOWN(('SPT-01'!$M42*'TABELA AUXILIAR'!$J$4+SUM('SPT-01'!$O$37:$O42))/2,0)*0.9 -> 2474.1 | M7: =ROUNDDOWN(('SPT-01'!$M42*'TABELA AUXILIAR'!$J$5+SUM('SPT-01'!$P$37:$P42))/2,0)*0.9 -> 3013.2 | O7: 22.2 | P7: =ROUNDDOWN(('SPT-01'!$M39*'TABELA AUXILIAR'!$J$3+SUM('SPT-01'!$N$34:$N39))/2,0)*0.9 -> 2682.9 | Q7: =ROUNDDOWN(('SPT-01'!$M39*'TABELA AUXILIAR'!$J$4+SUM('SPT-01'!$O$34:$O39))/2,0)*0.9 -> 3009.6 | R7: =ROUNDDOWN(('SPT-01'!$M39*'TABELA AUXILIAR'!$J$5+SUM('SPT-01'!$P$34:$P39))/2,0)*0.9 -> 3721.5 | T7: 17.4 | U7: =ROUNDDOWN(('SPT-01'!$M31*'TABELA AUXILIAR'!$J$3+SUM('SPT-01'!$N$26:$N31))/2,0)*0.9 -> 2176.2 | V7: =ROUNDDOWN(('SPT-01'!$M31*'TABELA AUXILIAR'!$J$4+SUM('SPT-01'!$O$26:$O31))/2,0)*0.9 -> 2449.8 | W7: =ROUNDDOWN(('SPT-01'!$M31*'TABELA AUXILIAR'!$J$5+SUM('SPT-01'!$P$26:$P31))/2,0)*0.9 -> 3050.1 | Y7: 12.6 | Z7: =ROUNDDOWN(('SPT-01'!$M23*'TABELA AUXILIAR'!$J$3+SUM('SPT-01'!$N$18:$N23))/2,0)*0.9 -> 1724.4 | AA7: =ROUNDDOWN(('SPT-01'!$M23*'TABELA AUXILIAR'!$J$4+SUM('SPT-01'!$O$18:$O23))/2,0)*0.9 -> 1946.7 | AB7: =ROUNDDOWN(('SPT-01'!$M23*'TABELA AUXILIAR'!$J$5+SUM('SPT-01'!$P$18:$P23))/2,0)*0.9 -> 2437.2 | AD7: 7.8 | AE7: =ROUNDDOWN(('SPT-01'!$M15*'TABELA AUXILIAR'!$J$3+SUM('SPT-01'!$N$10:$N15))/2,0)*0.9 -> 1301.4 | AF7: =ROUNDDOWN(('SPT-01'!$M15*'TABELA AUXILIAR'!$J$4+SUM('SPT-01'!$O$10:$O15))/2,0)*0.9 -> 1472.4 | AG7: =ROUNDDOWN(('SPT-01'!$M15*'TABELA AUXILIAR'!$J$5+SUM('SPT-01'!$P$10:$P15))/2,0)*0.9 -> 1850.4
J8: 24.6 | K8: =ROUNDDOWN(('SPT-01'!$M43*'TABELA AUXILIAR'!$J$3+SUM('SPT-01'!$N$37:$N43))/2,0)*0.9 -> 2988.9 | L8: =ROUNDDOWN(('SPT-01'!$M43*'TABELA AUXILIAR'!$J$4+SUM('SPT-01'!$O$37:$O43))/2,0)*0.9 -> 3346.2 | M8: =ROUNDDOWN(('SPT-01'!$M43*'TABELA AUXILIAR'!$J$5+SUM('SPT-01'!$P$37:$P43))/2,0)*0.9 -> 4122.9 | O8: 22.8 | P8: =ROUNDDOWN(('SPT-01'!$M40*'TABELA AUXILIAR'!$J$3+SUM('SPT-01'!$N$34:$N40))/2,0)*0.9 -> 2961.9 | Q8: =ROUNDDOWN(('SPT-01'!$M40*'TABELA AUXILIAR'!$J$4+SUM('SPT-01'!$O$34:$O40))/2,0)*0.9 -> 3312.9 | R8: =ROUNDDOWN(('SPT-01'!$M40*'TABELA AUXILIAR'!$J$5+SUM('SPT-01'!$P$34:$P40))/2,0)*0.9 -> 4075.2 | T8: 18 | U8: =ROUNDDOWN(('SPT-01'!$M32*'TABELA AUXILIAR'!$J$3+SUM('SPT-01'!$N$26:$N32))/2,0)*0.9 -> 2430 | V8: =ROUNDDOWN(('SPT-01'!$M32*'TABELA AUXILIAR'!$J$4+SUM('SPT-01'!$O$26:$O32))/2,0)*0.9 -> 2726.1 | W8: =ROUNDDOWN(('SPT-01'!$M32*'TABELA AUXILIAR'!$J$5+SUM('SPT-01'!$P$26:$P32))/2,0)*0.9 -> 3373.2 | Y8: 13.2 | Z8: =ROUNDDOWN(('SPT-01'!$M24*'TABELA AUXILIAR'!$J$3+SUM('SPT-01'!$N$18:$N24))/2,0)*0.9 -> 1752.3 | AA8: =ROUNDDOWN(('SPT-01'!$M24*'TABELA AUXILIAR'!$J$4+SUM('SPT-01'!$O$18:$O24))/2,0)*0.9 -> 1967.4 | AB8: =ROUNDDOWN(('SPT-01'!$M24*'TABELA AUXILIAR'!$J$5+SUM('SPT-01'!$P$18:$P24))/2,0)*0.9 -> 2437.2 | AD8: 8.4 | AE8: =ROUNDDOWN(('SPT-01'!$M16*'TABELA AUXILIAR'!$J$3+SUM('SPT-01'!$N$10:$N16))/2,0)*0.9 -> 1103.4 | AF8: =ROUNDDOWN(('SPT-01'!$M16*'TABELA AUXILIAR'!$J$4+SUM('SPT-01'!$O$10:$O16))/2,0)*0.9 -> 1233.9 | AG8: =ROUNDDOWN(('SPT-01'!$M16*'TABELA AUXILIAR'!$J$5+SUM('SPT-01'!$P$10:$P16))/2,0)*0.9 -> 1516.5
J9: 25.2 | K9: =ROUNDDOWN(('SPT-01'!$M44*'TABELA AUXILIAR'!$J$3+SUM('SPT-01'!$N$37:$N44))/2,0)*0.9 -> 3279.6 | L9: =ROUNDDOWN(('SPT-01'!$M44*'TABELA AUXILIAR'!$J$4+SUM('SPT-01'!$O$37:$O44))/2,0)*0.9 -> 3663 | M9: =ROUNDDOWN(('SPT-01'!$M44*'TABELA AUXILIAR'!$J$5+SUM('SPT-01'!$P$37:$P44))/2,0)*0.9 -> 4491 | O9: 23.4 | P9: =ROUNDDOWN(('SPT-01'!$M41*'TABELA AUXILIAR'!$J$3+SUM('SPT-01'!$N$34:$N41))/2,0)*0.9 -> 3243.6 | Q9: =ROUNDDOWN(('SPT-01'!$M41*'TABELA AUXILIAR'!$J$4+SUM('SPT-01'!$O$34:$O41))/2,0)*0.9 -> 3620.7 | R9: =ROUNDDOWN(('SPT-01'!$M41*'TABELA AUXILIAR'!$J$5+SUM('SPT-01'!$P$34:$P41))/2,0)*0.9 -> 4433.4 | T9: 18.6 | U9: =ROUNDDOWN(('SPT-01'!$M33*'TABELA AUXILIAR'!$J$3+SUM('SPT-01'!$N$26:$N33))/2,0)*0.9 -> 2687.4 | V9: =ROUNDDOWN(('SPT-01'!$M33*'TABELA AUXILIAR'!$J$4+SUM('SPT-01'!$O$26:$O33))/2,0)*0.9 -> 3006.9 | W9: =ROUNDDOWN(('SPT-01'!$M33*'TABELA AUXILIAR'!$J$5+SUM('SPT-01'!$P$26:$P33))/2,0)*0.9 -> 3699.9 | Y9: 13.8 | Z9: =ROUNDDOWN(('SPT-01'!$M25*'TABELA AUXILIAR'!$J$3+SUM('SPT-01'!$N$18:$N25))/2,0)*0.9 -> 2080.8 | AA9: =ROUNDDOWN(('SPT-01'!$M25*'TABELA AUXILIAR'!$J$4+SUM('SPT-01'!$O$18:$O25))/2,0)*0.9 -> 2337.3 | AB9: =ROUNDDOWN(('SPT-01'!$M25*'TABELA AUXILIAR'!$J$5+SUM('SPT-01'!$P$18:$P25))/2,0)*0.9 -> 2896.2 | AD9: 9 | AE9: =ROUNDDOWN(('SPT-01'!$M17*'TABELA AUXILIAR'!$J$3+SUM('SPT-01'!$N$10:$N17))/2,0)*0.9 -> 1152 | AF9: =ROUNDDOWN(('SPT-01'!$M17*'TABELA AUXILIAR'!$J$4+SUM('SPT-01'!$O$10:$O17))/2,0)*0.9 -> 1284.3 | AG9: =ROUNDDOWN(('SPT-01'!$M17*'TABELA AUXILIAR'!$J$5+SUM('SPT-01'!$P$10:$P17))/2,0)*0.9 -> 1568.7
J10: 25.8 | K10: =ROUNDDOWN(('SPT-01'!$M45*'TABELA AUXILIAR'!$J$3+SUM('SPT-01'!$N$37:$N45))/2,0)*0.9 -> 3573 | L10: =ROUNDDOWN(('SPT-01'!$M45*'TABELA AUXILIAR'!$J$4+SUM('SPT-01'!$O$37:$O45))/2,0)*0.9 -> 3982.5 | M10: =ROUNDDOWN(('SPT-01'!$M45*'TABELA AUXILIAR'!$J$5+SUM('SPT-01'!$P$37:$P45))/2,0)*0.9 -> 4863.6 | O10: 24 | P10: =ROUNDDOWN(('SPT-01'!$M42*'TABELA AUXILIAR'!$J$3+SUM('SPT-01'!$N$34:$N42))/2,0)*0.9 -> 2966.4 | Q10: =ROUNDDOWN(('SPT-01'!$M42*'TABELA AUXILIAR'!$J$4+SUM('SPT-01'!$O$34:$O42))/2,0)*0.9 -> 3281.4 | R10: =ROUNDDOWN(('SPT-01'!$M42*'TABELA AUXILIAR'!$J$5+SUM('SPT-01'!$P$34:$P42))/2,0)*0.9 -> 3945.6 | T10: 19.2 | U10: =ROUNDDOWN(('SPT-01'!$M34*'TABELA AUXILIAR'!$J$3+SUM('SPT-01'!$N$26:$N34))/2,0)*0.9 -> 2947.5 | V10: =ROUNDDOWN(('SPT-01'!$M34*'TABELA AUXILIAR'!$J$4+SUM('SPT-01'!$O$26:$O34))/2,0)*0.9 -> 3290.4 | W10: =ROUNDDOWN(('SPT-01'!$M34*'TABELA AUXILIAR'!$J$5+SUM('SPT-01'!$P$26:$P34))/2,0)*0.9 -> 4030.2 | Y10: 14.4 | Z10: =ROUNDDOWN(('SPT-01'!$M26*'TABELA AUXILIAR'!$J$3+SUM('SPT-01'!$N$18:$N26))/2,0)*0.9 -> 2276.1 | AA10: =ROUNDDOWN(('SPT-01'!$M26*'TABELA AUXILIAR'!$J$4+SUM('SPT-01'!$O$18:$O26))/2,0)*0.9 -> 2550.6 | AB10: =ROUNDDOWN(('SPT-01'!$M26*'TABELA AUXILIAR'!$J$5+SUM('SPT-01'!$P$18:$P26))/2,0)*0.9 -> 3147.3 | AD10: 9.6 | AE10: =ROUNDDOWN(('SPT-01'!$M18*'TABELA AUXILIAR'!$J$3+SUM('SPT-01'!$N$10:$N18))/2,0)*0.9 -> 1505.7 | AF10: =ROUNDDOWN(('SPT-01'!$M18*'TABELA AUXILIAR'!$J$4+SUM('SPT-01'!$O$10:$O18))/2,0)*0.9 -> 1687.5 | AG10: =ROUNDDOWN(('SPT-01'!$M18*'TABELA AUXILIAR'!$J$5+SUM('SPT-01'!$P$10:$P18))/2,0)*0.9 -> 2084.4
J11: 26.4 | K11: =ROUNDDOWN(('SPT-01'!$M46*'TABELA AUXILIAR'!$J$3+SUM('SPT-01'!$N$37:$N46))/2,0)*0.9 -> 3673.8 | L11: =ROUNDDOWN(('SPT-01'!$M46*'TABELA AUXILIAR'!$J$4+SUM('SPT-01'!$O$37:$O46))/2,0)*0.9 -> 4079.7 | M11: =ROUNDDOWN(('SPT-01'!$M46*'TABELA AUXILIAR'!$J$5+SUM('SPT-01'!$P$37:$P46))/2,0)*0.9 -> 4942.8 | O11: 24.6 | P11: =ROUNDDOWN(('SPT-01'!$M43*'TABELA AUXILIAR'!$J$3+SUM('SPT-01'!$N$34:$N43))/2,0)*0.9 -> 3732.3 | Q11: =ROUNDDOWN(('SPT-01'!$M43*'TABELA AUXILIAR'!$J$4+SUM('SPT-01'!$O$34:$O43))/2,0)*0.9 -> 4153.5 | R11: =ROUNDDOWN(('SPT-01'!$M43*'TABELA AUXILIAR'!$J$5+SUM('SPT-01'!$P$34:$P43))/2,0)*0.9 -> 5054.4 | T11: 19.8 | U11: =ROUNDDOWN(('SPT-01'!$M35*'TABELA AUXILIAR'!$J$3+SUM('SPT-01'!$N$26:$N35))/2,0)*0.9 -> 3210.3 | V11: =ROUNDDOWN(('SPT-01'!$M35*'TABELA AUXILIAR'!$J$4+SUM('SPT-01'!$O$26:$O35))/2,0)*0.9 -> 3577.5 | W11: =ROUNDDOWN(('SPT-01'!$M35*'TABELA AUXILIAR'!$J$5+SUM('SPT-01'!$P$26:$P35))/2,0)*0.9 -> 4365 | Y11: 15 | Z11: =ROUNDDOWN(('SPT-01'!$M27*'TABELA AUXILIAR'!$J$3+SUM('SPT-01'!$N$18:$N27))/2,0)*0.9 -> 2107.8 | AA11: =ROUNDDOWN(('SPT-01'!$M27*'TABELA AUXILIAR'!$J$4+SUM('SPT-01'!$O$18:$O27))/2,0)*0.9 -> 2342.7 | AB11: =ROUNDDOWN(('SPT-01'!$M27*'TABELA AUXILIAR'!$J$5+SUM('SPT-01'!$P$18:$P27))/2,0)*0.9 -> 2846.7 | AD11: 10.2 | AE11: =ROUNDDOWN(('SPT-01'!$M19*'TABELA AUXILIAR'!$J$3+SUM('SPT-01'!$N$10:$N19))/2,0)*0.9 -> 1817.1 | AF11: =ROUNDDOWN(('SPT-01'!$M19*'TABELA AUXILIAR'!$J$4+SUM('SPT-01'!$O$10:$O19))/2,0)*0.9 -> 2039.4 | AG11: =ROUNDDOWN(('SPT-01'!$M19*'TABELA AUXILIAR'!$J$5+SUM('SPT-01'!$P$10:$P19))/2,0)*0.9 -> 2525.4
J12: 27 | K12: =ROUNDDOWN(('SPT-01'!$M47*'TABELA AUXILIAR'!$J$3+SUM('SPT-01'!$N$37:$N47))/2,0)*0.9 -> 4140.9 | L12: =ROUNDDOWN(('SPT-01'!$M47*'TABELA AUXILIAR'!$J$4+SUM('SPT-01'!$O$37:$O47))/2,0)*0.9 -> 4601.7 | M12: =ROUNDDOWN(('SPT-01'!$M47*'TABELA AUXILIAR'!$J$5+SUM('SPT-01'!$P$37:$P47))/2,0)*0.9 -> 5583.6 | O12: 25.2 | P12: =ROUNDDOWN(('SPT-01'!$M44*'TABELA AUXILIAR'!$J$3+SUM('SPT-01'!$N$34:$N44))/2,0)*0.9 -> 4023.9 | Q12: =ROUNDDOWN(('SPT-01'!$M44*'TABELA AUXILIAR'!$J$4+SUM('SPT-01'!$O$34:$O44))/2,0)*0.9 -> 4470.3 | R12: =ROUNDDOWN(('SPT-01'!$M44*'TABELA AUXILIAR'!$J$5+SUM('SPT-01'!$P$34:$P44))/2,0)*0.9 -> 5423.4 | T12: 20.4 | U12: =ROUNDDOWN(('SPT-01'!$M36*'TABELA AUXILIAR'!$J$3+SUM('SPT-01'!$N$26:$N36))/2,0)*0.9 -> 3476.7 | V12: =ROUNDDOWN(('SPT-01'!$M36*'TABELA AUXILIAR'!$J$4+SUM('SPT-01'!$O$26:$O36))/2,0)*0.9 -> 3868.2 | W12: =ROUNDDOWN(('SPT-01'!$M36*'TABELA AUXILIAR'!$J$5+SUM('SPT-01'!$P$26:$P36))/2,0)*0.9 -> 4703.4 | Y12: 15.6 | Z12: =ROUNDDOWN(('SPT-01'!$M28*'TABELA AUXILIAR'!$J$3+SUM('SPT-01'!$N$18:$N28))/2,0)*0.9 -> 2187 | AA12: =ROUNDDOWN(('SPT-01'!$M28*'TABELA AUXILIAR'!$J$4+SUM('SPT-01'!$O$18:$O28))/2,0)*0.9 -> 2426.4 | AB12: =ROUNDDOWN(('SPT-01'!$M28*'TABELA AUXILIAR'!$J$5+SUM('SPT-01'!$P$18:$P28))/2,0)*0.9 -> 2934 | AD12: 10.8 | AE12: =ROUNDDOWN(('SPT-01'!$M20*'TABELA AUXILIAR'!$J$3+SUM('SPT-01'!$N$10:$N20))/2,0)*0.9 -> 1516.5 | AF12: =ROUNDDOWN(('SPT-01'!$M20*'TABELA AUXILIAR'!$J$4+SUM('SPT-01'!$O$10:$O20))/2,0)*0.9 -> 1682.1 | AG12: =ROUNDDOWN(('SPT-01'!$M20*'TABELA AUXILIAR'!$J$5+SUM('SPT-01'!$P$10:$P20))/2,0)*0.9 -> 2033.1
J13: 27.6 | K13: =ROUNDDOWN(('SPT-01'!$M48*'TABELA AUXILIAR'!$J$3+SUM('SPT-01'!$N$37:$N48))/2,0)*0.9 -> 4443.3 | L13: =ROUNDDOWN(('SPT-01'!$M48*'TABELA AUXILIAR'!$J$4+SUM('SPT-01'!$O$37:$O48))/2,0)*0.9 -> 4931.1 | M13: =ROUNDDOWN(('SPT-01'!$M48*'TABELA AUXILIAR'!$J$5+SUM('SPT-01'!$P$37:$P48))/2,0)*0.9 -> 5966.1 | O13: 25.8 | P13: =ROUNDDOWN(('SPT-01'!$M45*'TABELA AUXILIAR'!$J$3+SUM('SPT-01'!$N$34:$N45))/2,0)*0.9 -> 4317.3 | Q13: =ROUNDDOWN(('SPT-01'!$M45*'TABELA AUXILIAR'!$J$4+SUM('SPT-01'!$O$34:$O45))/2,0)*0.9 -> 4790.7 | R13: =ROUNDDOWN(('SPT-01'!$M45*'TABELA AUXILIAR'!$J$5+SUM('SPT-01'!$P$34:$P45))/2,0)*0.9 -> 5796 | T13: 21 | U13: =ROUNDDOWN(('SPT-01'!$M37*'TABELA AUXILIAR'!$J$3+SUM('SPT-01'!$N$26:$N37))/2,0)*0.9 -> 3615.3 | V13: =ROUNDDOWN(('SPT-01'!$M37*'TABELA AUXILIAR'!$J$4+SUM('SPT-01'!$O$26:$O37))/2,0)*0.9 -> 4009.5 | W13: =ROUNDDOWN(('SPT-01'!$M37*'TABELA AUXILIAR'!$J$5+SUM('SPT-01'!$P$26:$P37))/2,0)*0.9 -> 4846.5 | Y13: 16.2 | Z13: =ROUNDDOWN(('SPT-01'!$M29*'TABELA AUXILIAR'!$J$3+SUM('SPT-01'!$N$18:$N29))/2,0)*0.9 -> 2808.9 | AA13: =ROUNDDOWN(('SPT-01'!$M29*'TABELA AUXILIAR'!$J$4+SUM('SPT-01'!$O$18:$O29))/2,0)*0.9 -> 3133.8 | AB13: =ROUNDDOWN(('SPT-01'!$M29*'TABELA AUXILIAR'!$J$5+SUM('SPT-01'!$P$18:$P29))/2,0)*0.9 -> 3833.1 | AD13: 11.4 | AE13: =ROUNDDOWN(('SPT-01'!$M21*'TABELA AUXILIAR'!$J$3+SUM('SPT-01'!$N$10:$N21))/2,0)*0.9 -> 2097.9 | AF13: =ROUNDDOWN(('SPT-01'!$M21*'TABELA AUXILIAR'!$J$4+SUM('SPT-01'!$O$10:$O21))/2,0)*0.9 -> 2348.1 | AG13: =ROUNDDOWN(('SPT-01'!$M21*'TABELA AUXILIAR'!$J$5+SUM('SPT-01'!$P$10:$P21))/2,0)*0.9 -> 2891.7
J14: 28.2 | K14: =ROUNDDOWN(('SPT-01'!$M49*'TABELA AUXILIAR'!$J$3+SUM('SPT-01'!$N$37:$N49))/2,0)*0.9 -> 4704.3 | L14: =ROUNDDOWN(('SPT-01'!$M49*'TABELA AUXILIAR'!$J$4+SUM('SPT-01'!$O$37:$O49))/2,0)*0.9 -> 5215.5 | M14: =ROUNDDOWN(('SPT-01'!$M49*'TABELA AUXILIAR'!$J$5+SUM('SPT-01'!$P$37:$P49))/2,0)*0.9 -> 6298.2 | O14: 26.4 | P14: =ROUNDDOWN(('SPT-01'!$M46*'TABELA AUXILIAR'!$J$3+SUM('SPT-01'!$N$34:$N46))/2,0)*0.9 -> 4418.1 | Q14: =ROUNDDOWN(('SPT-01'!$M46*'TABELA AUXILIAR'!$J$4+SUM('SPT-01'!$O$34:$O46))/2,0)*0.9 -> 4887 | R14: =ROUNDDOWN(('SPT-01'!$M46*'TABELA AUXILIAR'!$J$5+SUM('SPT-01'!$P$34:$P46))/2,0)*0.9 -> 5875.2 | T14: 21.6 | U14: =ROUNDDOWN(('SPT-01'!$M38*'TABELA AUXILIAR'!$J$3+SUM('SPT-01'!$N$26:$N38))/2,0)*0.9 -> 4000.5 | V14: =ROUNDDOWN(('SPT-01'!$M38*'TABELA AUXILIAR'!$J$4+SUM('SPT-01'!$O$26:$O38))/2,0)*0.9 -> 4437.9 | W14: =ROUNDDOWN(('SPT-01'!$M38*'TABELA AUXILIAR'!$J$5+SUM('SPT-01'!$P$26:$P38))/2,0)*0.9 -> 5367.6 | Y14: 16.8 | Z14: =ROUNDDOWN(('SPT-01'!$M30*'TABELA AUXILIAR'!$J$3+SUM('SPT-01'!$N$18:$N30))/2,0)*0.9 -> 3056.4 | AA14: =ROUNDDOWN(('SPT-01'!$M30*'TABELA AUXILIAR'!$J$4+SUM('SPT-01'!$O$18:$O30))/2,0)*0.9 -> 3402.9 | AB14: =ROUNDDOWN(('SPT-01'!$M30*'TABELA AUXILIAR'!$J$5+SUM('SPT-01'!$P$18:$P30))/2,0)*0.9 -> 4147.2 | AD14: 12 | AE14: =ROUNDDOWN(('SPT-01'!$M22*'TABELA AUXILIAR'!$J$3+SUM('SPT-01'!$N$10:$N22))/2,0)*0.9 -> 2277.9 | AF14: =ROUNDDOWN(('SPT-01'!$M22*'TABELA AUXILIAR'!$J$4+SUM('SPT-01'!$O$10:$O22))/2,0)*0.9 -> 2545.2 | AG14: =ROUNDDOWN(('SPT-01'!$M22*'TABELA AUXILIAR'!$J$5+SUM('SPT-01'!$P$10:$P22))/2,0)*0.9 -> 3123.9
J15: 28.8 | K15: =ROUNDDOWN(('SPT-01'!$M50*'TABELA AUXILIAR'!$J$3+SUM('SPT-01'!$N$37:$N50))/2,0)*0.9 -> 4970.7 | L15: =ROUNDDOWN(('SPT-01'!$M50*'TABELA AUXILIAR'!$J$4+SUM('SPT-01'!$O$37:$O50))/2,0)*0.9 -> 5505.3 | M15: =ROUNDDOWN(('SPT-01'!$M50*'TABELA AUXILIAR'!$J$5+SUM('SPT-01'!$P$37:$P50))/2,0)*0.9 -> 6636.6 | O15: 27 | P15: =ROUNDDOWN(('SPT-01'!$M47*'TABELA AUXILIAR'!$J$3+SUM('SPT-01'!$N$34:$N47))/2,0)*0.9 -> 4885.2 | Q15: =ROUNDDOWN(('SPT-01'!$M47*'TABELA AUXILIAR'!$J$4+SUM('SPT-01'!$O$34:$O47))/2,0)*0.9 -> 5409 | R15: =ROUNDDOWN(('SPT-01'!$M47*'TABELA AUXILIAR'!$J$5+SUM('SPT-01'!$P$34:$P47))/2,0)*0.9 -> 6516 | T15: 22.2 | U15: =ROUNDDOWN(('SPT-01'!$M39*'TABELA AUXILIAR'!$J$3+SUM('SPT-01'!$N$26:$N39))/2,0)*0.9 -> 4275.9 | V15: =ROUNDDOWN(('SPT-01'!$M39*'TABELA AUXILIAR'!$J$4+SUM('SPT-01'!$O$26:$O39))/2,0)*0.9 -> 4738.5 | W15: =ROUNDDOWN(('SPT-01'!$M39*'TABELA AUXILIAR'!$J$5+SUM('SPT-01'!$P$26:$P39))/2,0)*0.9 -> 5717.7 | Y15: 17.4 | Z15: =ROUNDDOWN(('SPT-01'!$M31*'TABELA AUXILIAR'!$J$3+SUM('SPT-01'!$N$18:$N31))/2,0)*0.9 -> 3306.6 | AA15: =ROUNDDOWN(('SPT-01'!$M31*'TABELA AUXILIAR'!$J$4+SUM('SPT-01'!$O$18:$O31))/2,0)*0.9 -> 3676.5 | AB15: =ROUNDDOWN(('SPT-01'!$M31*'TABELA AUXILIAR'!$J$5+SUM('SPT-01'!$P$18:$P31))/2,0)*0.9 -> 4465.8 | AD15: 12.6 | AE15: =ROUNDDOWN(('SPT-01'!$M23*'TABELA AUXILIAR'!$J$3+SUM('SPT-01'!$N$10:$N23))/2,0)*0.9 -> 2462.4 | AF15: =ROUNDDOWN(('SPT-01'!$M23*'TABELA AUXILIAR'!$J$4+SUM('SPT-01'!$O$10:$O23))/2,0)*0.9 -> 2746.8 | AG15: =ROUNDDOWN(('SPT-01'!$M23*'TABELA AUXILIAR'!$J$5+SUM('SPT-01'!$P$10:$P23))/2,0)*0.9 -> 3361.5
J16: 29.4 | K16: =ROUNDDOWN(('SPT-01'!$M51*'TABELA AUXILIAR'!$J$3+SUM('SPT-01'!$N$37:$N51))/2,0)*0.9 -> 5239.8 | L16: =ROUNDDOWN(('SPT-01'!$M51*'TABELA AUXILIAR'!$J$4+SUM('SPT-01'!$O$37:$O51))/2,0)*0.9 -> 5798.7 | M16: =ROUNDDOWN(('SPT-01'!$M51*'TABELA AUXILIAR'!$J$5+SUM('SPT-01'!$P$37:$P51))/2,0)*0.9 -> 6978.6 | O16: 27.6 | P16: =ROUNDDOWN(('SPT-01'!$M48*'TABELA AUXILIAR'!$J$3+SUM('SPT-01'!$N$34:$N48))/2,0)*0.9 -> 5187.6 | Q16: =ROUNDDOWN(('SPT-01'!$M48*'TABELA AUXILIAR'!$J$4+SUM('SPT-01'!$O$34:$O48))/2,0)*0.9 -> 5738.4 | R16: =ROUNDDOWN(('SPT-01'!$M48*'TABELA AUXILIAR'!$J$5+SUM('SPT-01'!$P$34:$P48))/2,0)*0.9 -> 6898.5 | T16: 22.8 | U16: =ROUNDDOWN(('SPT-01'!$M40*'TABELA AUXILIAR'!$J$3+SUM('SPT-01'!$N$26:$N40))/2,0)*0.9 -> 4554.9 | V16: =ROUNDDOWN(('SPT-01'!$M40*'TABELA AUXILIAR'!$J$4+SUM('SPT-01'!$O$26:$O40))/2,0)*0.9 -> 5041.8 | W16: =ROUNDDOWN(('SPT-01'!$M40*'TABELA AUXILIAR'!$J$5+SUM('SPT-01'!$P$26:$P40))/2,0)*0.9 -> 6071.4 | Y16: 18 | Z16: =ROUNDDOWN(('SPT-01'!$M32*'TABELA AUXILIAR'!$J$3+SUM('SPT-01'!$N$18:$N32))/2,0)*0.9 -> 3560.4 | AA16: =ROUNDDOWN(('SPT-01'!$M32*'TABELA AUXILIAR'!$J$4+SUM('SPT-01'!$O$18:$O32))/2,0)*0.9 -> 3952.8 | AB16: =ROUNDDOWN(('SPT-01'!$M32*'TABELA AUXILIAR'!$J$5+SUM('SPT-01'!$P$18:$P32))/2,0)*0.9 -> 4788.9 | AD16: 13.2 | AE16: =ROUNDDOWN(('SPT-01'!$M24*'TABELA AUXILIAR'!$J$3+SUM('SPT-01'!$N$10:$N24))/2,0)*0.9 -> 2490.3 | AF16: =ROUNDDOWN(('SPT-01'!$M24*'TABELA AUXILIAR'!$J$4+SUM('SPT-01'!$O$10:$O24))/2,0)*0.9 -> 2768.4 | AG16: =ROUNDDOWN(('SPT-01'!$M24*'TABELA AUXILIAR'!$J$5+SUM('SPT-01'!$P$10:$P24))/2,0)*0.9 -> 3361.5
J17: 30 | K17: =ROUNDDOWN(('SPT-01'!$M52*'TABELA AUXILIAR'!$J$3+SUM('SPT-01'!$N$37:$N52))/2,0)*0.9 -> 5512.5 | L17: =ROUNDDOWN(('SPT-01'!$M52*'TABELA AUXILIAR'!$J$4+SUM('SPT-01'!$O$37:$O52))/2,0)*0.9 -> 6095.7 | M17: =ROUNDDOWN(('SPT-01'!$M52*'TABELA AUXILIAR'!$J$5+SUM('SPT-01'!$P$37:$P52))/2,0)*0.9 -> 7325.1 | O17: 28.2 | P17: =ROUNDDOWN(('SPT-01'!$M49*'TABELA AUXILIAR'!$J$3+SUM('SPT-01'!$N$34:$N49))/2,0)*0.9 -> 5448.6 | Q17: =ROUNDDOWN(('SPT-01'!$M49*'TABELA AUXILIAR'!$J$4+SUM('SPT-01'!$O$34:$O49))/2,0)*0.9 -> 6022.8 | R17: =ROUNDDOWN(('SPT-01'!$M49*'TABELA AUXILIAR'!$J$5+SUM('SPT-01'!$P$34:$P49))/2,0)*0.9 -> 7230.6 | T17: 23.4 | U17: =ROUNDDOWN(('SPT-01'!$M41*'TABELA AUXILIAR'!$J$3+SUM('SPT-01'!$N$26:$N41))/2,0)*0.9 -> 4836.6 | V17: =ROUNDDOWN(('SPT-01'!$M41*'TABELA AUXILIAR'!$J$4+SUM('SPT-01'!$O$26:$O41))/2,0)*0.9 -> 5349.6 | W17: =ROUNDDOWN(('SPT-01'!$M41*'TABELA AUXILIAR'!$J$5+SUM('SPT-01'!$P$26:$P41))/2,0)*0.9 -> 6428.7 | Y17: 18.6 | Z17: =ROUNDDOWN(('SPT-01'!$M33*'TABELA AUXILIAR'!$J$3+SUM('SPT-01'!$N$18:$N33))/2,0)*0.9 -> 3817.8 | AA17: =ROUNDDOWN(('SPT-01'!$M33*'TABELA AUXILIAR'!$J$4+SUM('SPT-01'!$O$18:$O33))/2,0)*0.9 -> 4233.6 | AB17: =ROUNDDOWN(('SPT-01'!$M33*'TABELA AUXILIAR'!$J$5+SUM('SPT-01'!$P$18:$P33))/2,0)*0.9 -> 5115.6 | AD17: 13.8 | AE17: =ROUNDDOWN(('SPT-01'!$M25*'TABELA AUXILIAR'!$J$3+SUM('SPT-01'!$N$10:$N25))/2,0)*0.9 -> 2818.8 | AF17: =ROUNDDOWN(('SPT-01'!$M25*'TABELA AUXILIAR'!$J$4+SUM('SPT-01'!$O$10:$O25))/2,0)*0.9 -> 3137.4 | AG17: =ROUNDDOWN(('SPT-01'!$M25*'TABELA AUXILIAR'!$J$5+SUM('SPT-01'!$P$10:$P25))/2,0)*0.9 -> 3820.5
J18: 30.6 | K18: =ROUNDDOWN(('SPT-01'!$M53*'TABELA AUXILIAR'!$J$3+SUM('SPT-01'!$N$37:$N53))/2,0)*0.9 -> 5787.9 | L18: =ROUNDDOWN(('SPT-01'!$M53*'TABELA AUXILIAR'!$J$4+SUM('SPT-01'!$O$37:$O53))/2,0)*0.9 -> 6396.3 | M18: =ROUNDDOWN(('SPT-01'!$M53*'TABELA AUXILIAR'!$J$5+SUM('SPT-01'!$P$37:$P53))/2,0)*0.9 -> 7676.1 | O18: 28.8 | P18: =ROUNDDOWN(('SPT-01'!$M50*'TABELA AUXILIAR'!$J$3+SUM('SPT-01'!$N$34:$N50))/2,0)*0.9 -> 5715 | Q18: =ROUNDDOWN(('SPT-01'!$M50*'TABELA AUXILIAR'!$J$4+SUM('SPT-01'!$O$34:$O50))/2,0)*0.9 -> 6312.6 | R18: =ROUNDDOWN(('SPT-01'!$M50*'TABELA AUXILIAR'!$J$5+SUM('SPT-01'!$P$34:$P50))/2,0)*0.9 -> 7569 | T18: 24 | U18: =ROUNDDOWN(('SPT-01'!$M42*'TABELA AUXILIAR'!$J$3+SUM('SPT-01'!$N$26:$N42))/2,0)*0.9 -> 4560.3 | V18: =ROUNDDOWN(('SPT-01'!$M42*'TABELA AUXILIAR'!$J$4+SUM('SPT-01'!$O$26:$O42))/2,0)*0.9 -> 5010.3 | W18: =ROUNDDOWN(('SPT-01'!$M42*'TABELA AUXILIAR'!$J$5+SUM('SPT-01'!$P$26:$P42))/2,0)*0.9 -> 5940.9 | Y18: 19.2 | Z18: =ROUNDDOWN(('SPT-01'!$M34*'TABELA AUXILIAR'!$J$3+SUM('SPT-01'!$N$18:$N34))/2,0)*0.9 -> 4077.9 | AA18: =ROUNDDOWN(('SPT-01'!$M34*'TABELA AUXILIAR'!$J$4+SUM('SPT-01'!$O$18:$O34))/2,0)*0.9 -> 4517.1 | AB18: =ROUNDDOWN(('SPT-01'!$M34*'TABELA AUXILIAR'!$J$5+SUM('SPT-01'!$P$18:$P34))/2,0)*0.9 -> 5445.9 | AD18: 14.4 | AE18: =ROUNDDOWN(('SPT-01'!$M26*'TABELA AUXILIAR'!$J$3+SUM('SPT-01'!$N$10:$N26))/2,0)*0.9 -> 3014.1 | AF18: =ROUNDDOWN(('SPT-01'!$M26*'TABELA AUXILIAR'!$J$4+SUM('SPT-01'!$O$10:$O26))/2,0)*0.9 -> 3351.6 | AG18: =ROUNDDOWN(('SPT-01'!$M26*'TABELA AUXILIAR'!$J$5+SUM('SPT-01'!$P$10:$P26))/2,0)*0.9 -> 4071.6
J19: 31.2 | K19: =ROUNDDOWN(('SPT-01'!$M54*'TABELA AUXILIAR'!$J$3+SUM('SPT-01'!$N$37:$N54))/2,0)*0.9 -> 5334.3 | L19: =ROUNDDOWN(('SPT-01'!$M54*'TABELA AUXILIAR'!$J$4+SUM('SPT-01'!$O$37:$O54))/2,0)*0.9 -> 5853.6 | M19: =ROUNDDOWN(('SPT-01'!$M54*'TABELA AUXILIAR'!$J$5+SUM('SPT-01'!$P$37:$P54))/2,0)*0.9 -> 6921.9 | O19: 29.4 | P19: =ROUNDDOWN(('SPT-01'!$M51*'TABELA AUXILIAR'!$J$3+SUM('SPT-01'!$N$34:$N51))/2,0)*0.9 -> 5984.1 | Q19: =ROUNDDOWN(('SPT-01'!$M51*'TABELA AUXILIAR'!$J$4+SUM('SPT-01'!$O$34:$O51))/2,0)*0.9 -> 6606.9 | R19: =ROUNDDOWN(('SPT-01'!$M51*'TABELA AUXILIAR'!$J$5+SUM('SPT-01'!$P$34:$P51))/2,0)*0.9 -> 7911 | T19: 24.6 | U19: =ROUNDDOWN(('SPT-01'!$M43*'TABELA AUXILIAR'!$J$3+SUM('SPT-01'!$N$26:$N43))/2,0)*0.9 -> 5326.2 | V19: =ROUNDDOWN(('SPT-01'!$M43*'TABELA AUXILIAR'!$J$4+SUM('SPT-01'!$O$26:$O43))/2,0)*0.9 -> 5882.4 | W19: =ROUNDDOWN(('SPT-01'!$M43*'TABELA AUXILIAR'!$J$5+SUM('SPT-01'!$P$26:$P43))/2,0)*0.9 -> 7050.6 | Y19: 19.8 | Z19: =ROUNDDOWN(('SPT-01'!$M35*'TABELA AUXILIAR'!$J$3+SUM('SPT-01'!$N$18:$N35))/2,0)*0.9 -> 4340.7 | AA19: =ROUNDDOWN(('SPT-01'!$M35*'TABELA AUXILIAR'!$J$4+SUM('SPT-01'!$O$18:$O35))/2,0)*0.9 -> 4804.2 | AB19: =ROUNDDOWN(('SPT-01'!$M35*'TABELA AUXILIAR'!$J$5+SUM('SPT-01'!$P$18:$P35))/2,0)*0.9 -> 5780.7 | AD19: 15 | AE19: =ROUNDDOWN(('SPT-01'!$M27*'TABELA AUXILIAR'!$J$3+SUM('SPT-01'!$N$10:$N27))/2,0)*0.9 -> 2844.9 | AF19: =ROUNDDOWN(('SPT-01'!$M27*'TABELA AUXILIAR'!$J$4+SUM('SPT-01'!$O$10:$O27))/2,0)*0.9 -> 3143.7 | AG19: =ROUNDDOWN(('SPT-01'!$M27*'TABELA AUXILIAR'!$J$5+SUM('SPT-01'!$P$10:$P27))/2,0)*0.9 -> 3771
... J182: 129 | K182: =ROUNDDOWN(('SPT-01'!$M217*'TABELA AUXILIAR'!$J$3+SUM('SPT-01'!$N$37:$N217))/2,0)*0.9 -> 65241 | L182: =ROUNDDOWN(('SPT-01'!$M217*'TABELA AUXILIAR'!$J$4+SUM('SPT-01'!$O$37:$O217))/2,0)*0.9 -> 70947.9 | M182: =ROUNDDOWN(('SPT-01'!$M217*'TABELA AUXILIAR'!$J$5+SUM('SPT-01'!$P$37:$P217))/2,0)*0.9 -> 82289.7 | O182: 127.2 | P182: =ROUNDDOWN(('SPT-01'!$M214*'TABELA AUXILIAR'!$J$3+SUM('SPT-01'!$N$34:$N214))/2,0)*0.9 -> 64571.4 | Q182: =ROUNDDOWN(('SPT-01'!$M214*'TABELA AUXILIAR'!$J$4+SUM('SPT-01'!$O$34:$O214))/2,0)*0.9 -> 70219.8 | R182: =ROUNDDOWN(('SPT-01'!$M214*'TABELA AUXILIAR'!$J$5+SUM('SPT-01'!$P$34:$P214))/2,0)*0.9 -> 81446.4 | T182: 122.4 | U182: =ROUNDDOWN(('SPT-01'!$M206*'TABELA AUXILIAR'!$J$3+SUM('SPT-01'!$N$26:$N206))/2,0)*0.9 -> 62448.3 | V182: =ROUNDDOWN(('SPT-01'!$M206*'TABELA AUXILIAR'!$J$4+SUM('SPT-01'!$O$26:$O206))/2,0)*0.9 -> 67913.1 | W182: =ROUNDDOWN(('SPT-01'!$M206*'TABELA AUXILIAR'!$J$5+SUM('SPT-01'!$P$26:$P206))/2,0)*0.9 -> 78775.2 | Y182: 117.6 | Z182: =ROUNDDOWN(('SPT-01'!$M198*'TABELA AUXILIAR'!$J$3+SUM('SPT-01'!$N$18:$N198))/2,0)*0.9 -> 59942.7 | AA182: =ROUNDDOWN(('SPT-01'!$M198*'TABELA AUXILIAR'!$J$4+SUM('SPT-01'!$O$18:$O198))/2,0)*0.9 -> 65189.7 | AB182: =ROUNDDOWN(('SPT-01'!$M198*'TABELA AUXILIAR'!$J$5+SUM('SPT-01'!$P$18:$P198))/2,0)*0.9 -> 75623.4 | AD182: 112.8 | AE182: =ROUNDDOWN(('SPT-01'!$M190*'TABELA AUXILIAR'!$J$3+SUM('SPT-01'!$N$10:$N190))/2,0)*0.9 -> 57124.8 | AF182: =ROUNDDOWN(('SPT-01'!$M190*'TABELA AUXILIAR'!$J$4+SUM('SPT-01'!$O$10:$O190))/2,0)*0.9 -> 62128.8 | AG182: =ROUNDDOWN(('SPT-01'!$M190*'TABELA AUXILIAR'!$J$5+SUM('SPT-01'!$P$10:$P190))/2,0)*0.9 -> 72081.9
O183: 127.8 | P183: =ROUNDDOWN(('SPT-01'!$M215*'TABELA AUXILIAR'!$J$3+SUM('SPT-01'!$N$34:$N215))/2,0)*0.9 -> 65041.2 | Q183: =ROUNDDOWN(('SPT-01'!$M215*'TABELA AUXILIAR'!$J$4+SUM('SPT-01'!$O$34:$O215))/2,0)*0.9 -> 70730.1 | R183: =ROUNDDOWN(('SPT-01'!$M215*'TABELA AUXILIAR'!$J$5+SUM('SPT-01'!$P$34:$P215))/2,0)*0.9 -> 82036.8 | T183: 123 | U183: =ROUNDDOWN(('SPT-01'!$M207*'TABELA AUXILIAR'!$J$3+SUM('SPT-01'!$N$26:$N207))/2,0)*0.9 -> 62909.1 | V183: =ROUNDDOWN(('SPT-01'!$M207*'TABELA AUXILIAR'!$J$4+SUM('SPT-01'!$O$26:$O207))/2,0)*0.9 -> 68412.6 | W183: =ROUNDDOWN(('SPT-01'!$M207*'TABELA AUXILIAR'!$J$5+SUM('SPT-01'!$P$26:$P207))/2,0)*0.9 -> 79353 | Y183: 118.2 | Z183: =ROUNDDOWN(('SPT-01'!$M199*'TABELA AUXILIAR'!$J$3+SUM('SPT-01'!$N$18:$N199))/2,0)*0.9 -> 60392.7 | AA183: =ROUNDDOWN(('SPT-01'!$M199*'TABELA AUXILIAR'!$J$4+SUM('SPT-01'!$O$18:$O199))/2,0)*0.9 -> 65678.4 | AB183: =ROUNDDOWN(('SPT-01'!$M199*'TABELA AUXILIAR'!$J$5+SUM('SPT-01'!$P$18:$P199))/2,0)*0.9 -> 76189.5 | AD183: 113.4 | AE183: =ROUNDDOWN(('SPT-01'!$M191*'TABELA AUXILIAR'!$J$3+SUM('SPT-01'!$N$10:$N191))/2,0)*0.9 -> 57564.9 | AF183: =ROUNDDOWN(('SPT-01'!$M191*'TABELA AUXILIAR'!$J$4+SUM('SPT-01'!$O$10:$O191))/2,0)*0.9 -> 62606.7 | AG183: =ROUNDDOWN(('SPT-01'!$M191*'TABELA AUXILIAR'!$J$5+SUM('SPT-01'!$P$10:$P191))/2,0)*0.9 -> 72634.5
O184: 128.4 | P184: =ROUNDDOWN(('SPT-01'!$M216*'TABELA AUXILIAR'!$J$3+SUM('SPT-01'!$N$34:$N216))/2,0)*0.9 -> 65512.8 | Q184: =ROUNDDOWN(('SPT-01'!$M216*'TABELA AUXILIAR'!$J$4+SUM('SPT-01'!$O$34:$O216))/2,0)*0.9 -> 71242.2 | R184: =ROUNDDOWN(('SPT-01'!$M216*'TABELA AUXILIAR'!$J$5+SUM('SPT-01'!$P$34:$P216))/2,0)*0.9 -> 82628.1 | T184: 123.6 | U184: =ROUNDDOWN(('SPT-01'!$M208*'TABELA AUXILIAR'!$J$3+SUM('SPT-01'!$N$26:$N208))/2,0)*0.9 -> 63369.9 | V184: =ROUNDDOWN(('SPT-01'!$M208*'TABELA AUXILIAR'!$J$4+SUM('SPT-01'!$O$26:$O208))/2,0)*0.9 -> 68913.9 | W184: =ROUNDDOWN(('SPT-01'!$M208*'TABELA AUXILIAR'!$J$5+SUM('SPT-01'!$P$26:$P208))/2,0)*0.9 -> 79932.6 | Y184: 118.8 | Z184: =ROUNDDOWN(('SPT-01'!$M200*'TABELA AUXILIAR'!$J$3+SUM('SPT-01'!$N$18:$N200))/2,0)*0.9 -> 60843.6 | AA184: =ROUNDDOWN(('SPT-01'!$M200*'TABELA AUXILIAR'!$J$4+SUM('SPT-01'!$O$18:$O200))/2,0)*0.9 -> 66168.9 | AB184: =ROUNDDOWN(('SPT-01'!$M200*'TABELA AUXILIAR'!$J$5+SUM('SPT-01'!$P$18:$P200))/2,0)*0.9 -> 76756.5 | AD184: 114 | AE184: =ROUNDDOWN(('SPT-01'!$M192*'TABELA AUXILIAR'!$J$3+SUM('SPT-01'!$N$10:$N192))/2,0)*0.9 -> 58005.9 | AF184: =ROUNDDOWN(('SPT-01'!$M192*'TABELA AUXILIAR'!$J$4+SUM('SPT-01'!$O$10:$O192))/2,0)*0.9 -> 63086.4 | AG184: =ROUNDDOWN(('SPT-01'!$M192*'TABELA AUXILIAR'!$J$5+SUM('SPT-01'!$P$10:$P192))/2,0)*0.9 -> 73188.9
O185: 129 | P185: =ROUNDDOWN(('SPT-01'!$M217*'TABELA AUXILIAR'!$J$3+SUM('SPT-01'!$N$34:$N217))/2,0)*0.9 -> 65985.3 | Q185: =ROUNDDOWN(('SPT-01'!$M217*'TABELA AUXILIAR'!$J$4+SUM('SPT-01'!$O$34:$O217))/2,0)*0.9 -> 71755.2 | R185: =ROUNDDOWN(('SPT-01'!$M217*'TABELA AUXILIAR'!$J$5+SUM('SPT-01'!$P$34:$P217))/2,0)*0.9 -> 83222.1 | T185: 124.2 | U185: =ROUNDDOWN(('SPT-01'!$M209*'TABELA AUXILIAR'!$J$3+SUM('SPT-01'!$N$26:$N209))/2,0)*0.9 -> 63833.4 | V185: =ROUNDDOWN(('SPT-01'!$M209*'TABELA AUXILIAR'!$J$4+SUM('SPT-01'!$O$26:$O209))/2,0)*0.9 -> 69416.1 | W185: =ROUNDDOWN(('SPT-01'!$M209*'TABELA AUXILIAR'!$J$5+SUM('SPT-01'!$P$26:$P209))/2,0)*0.9 -> 80514 | Y185: 119.4 | Z185: =ROUNDDOWN(('SPT-01'!$M201*'TABELA AUXILIAR'!$J$3+SUM('SPT-01'!$N$18:$N201))/2,0)*0.9 -> 61296.3 | AA185: =ROUNDDOWN(('SPT-01'!$M201*'TABELA AUXILIAR'!$J$4+SUM('SPT-01'!$O$18:$O201))/2,0)*0.9 -> 66660.3 | AB185: =ROUNDDOWN(('SPT-01'!$M201*'TABELA AUXILIAR'!$J$5+SUM('SPT-01'!$P$18:$P201))/2,0)*0.9 -> 77324.4 | AD185: 114.6 | AE185: =ROUNDDOWN(('SPT-01'!$M193*'TABELA AUXILIAR'!$J$3+SUM('SPT-01'!$N$10:$N193))/2,0)*0.9 -> 58448.7 | AF185: =ROUNDDOWN(('SPT-01'!$M193*'TABELA AUXILIAR'!$J$4+SUM('SPT-01'!$O$10:$O193))/2,0)*0.9 -> 63567 | AG185: =ROUNDDOWN(('SPT-01'!$M193*'TABELA AUXILIAR'!$J$5+SUM('SPT-01'!$P$10:$P193))/2,0)*0.9 -> 73744.2
O186: 129.6 | P186: =ROUNDDOWN(('SPT-01'!$M218*'TABELA AUXILIAR'!$J$3+SUM('SPT-01'!$N$34:$N218))/2,0)*0.9 -> 66459.6 | Q186: =ROUNDDOWN(('SPT-01'!$M218*'TABELA AUXILIAR'!$J$4+SUM('SPT-01'!$O$34:$O218))/2,0)*0.9 -> 72269.1 | R186: =ROUNDDOWN(('SPT-01'!$M218*'TABELA AUXILIAR'!$J$5+SUM('SPT-01'!$P$34:$P218))/2,0)*0.9 -> 83817 | T186: 124.8 | U186: =ROUNDDOWN(('SPT-01'!$M210*'TABELA AUXILIAR'!$J$3+SUM('SPT-01'!$N$26:$N210))/2,0)*0.9 -> 64296.9 | V186: =ROUNDDOWN(('SPT-01'!$M210*'TABELA AUXILIAR'!$J$4+SUM('SPT-01'!$O$26:$O210))/2,0)*0.9 -> 69920.1 | W186: =ROUNDDOWN(('SPT-01'!$M210*'TABELA AUXILIAR'!$J$5+SUM('SPT-01'!$P$26:$P210))/2,0)*0.9 -> 81096.3 | Y186: 120 | Z186: =ROUNDDOWN(('SPT-01'!$M202*'TABELA AUXILIAR'!$J$3+SUM('SPT-01'!$N$18:$N202))/2,0)*0.9 -> 61750.8 | AA186: =ROUNDDOWN(('SPT-01'!$M202*'TABELA AUXILIAR'!$J$4+SUM('SPT-01'!$O$18:$O202))/2,0)*0.9 -> 67153.5 | AB186: =ROUNDDOWN(('SPT-01'!$M202*'TABELA AUXILIAR'!$J$5+SUM('SPT-01'!$P$18:$P202))/2,0)*0.9 -> 77895 | AD186: 115.2 | AE186: =ROUNDDOWN(('SPT-01'!$M194*'TABELA AUXILIAR'!$J$3+SUM('SPT-01'!$N$10:$N194))/2,0)*0.9 -> 58892.4 | AF186: =ROUNDDOWN(('SPT-01'!$M194*'TABELA AUXILIAR'!$J$4+SUM('SPT-01'!$O$10:$O194))/2,0)*0.9 -> 64048.5 | AG186: =ROUNDDOWN(('SPT-01'!$M194*'TABELA AUXILIAR'!$J$5+SUM('SPT-01'!$P$10:$P194))/2,0)*0.9 -> 74302.2
O187: 130.2 | P187: =ROUNDDOWN(('SPT-01'!$M219*'TABELA AUXILIAR'!$J$3+SUM('SPT-01'!$N$34:$N219))/2,0)*0.9 -> 66933.9 | Q187: =ROUNDDOWN(('SPT-01'!$M219*'TABELA AUXILIAR'!$J$4+SUM('SPT-01'!$O$34:$O219))/2,0)*0.9 -> 72785.7 | R187: =ROUNDDOWN(('SPT-01'!$M219*'TABELA AUXILIAR'!$J$5+SUM('SPT-01'!$P$34:$P219))/2,0)*0.9 -> 84412.8 | T187: 125.4 | U187: =ROUNDDOWN(('SPT-01'!$M211*'TABELA AUXILIAR'!$J$3+SUM('SPT-01'!$N$26:$N211))/2,0)*0.9 -> 64762.2 | V187: =ROUNDDOWN(('SPT-01'!$M211*'TABELA AUXILIAR'!$J$4+SUM('SPT-01'!$O$26:$O211))/2,0)*0.9 -> 70425 | W187: =ROUNDDOWN(('SPT-01'!$M211*'TABELA AUXILIAR'!$J$5+SUM('SPT-01'!$P$26:$P211))/2,0)*0.9 -> 81680.4 | Y187: 120.6 | Z187: =ROUNDDOWN(('SPT-01'!$M203*'TABELA AUXILIAR'!$J$3+SUM('SPT-01'!$N$18:$N203))/2,0)*0.9 -> 62206.2 | AA187: =ROUNDDOWN(('SPT-01'!$M203*'TABELA AUXILIAR'!$J$4+SUM('SPT-01'!$O$18:$O203))/2,0)*0.9 -> 67648.5 | AB187: =ROUNDDOWN(('SPT-01'!$M203*'TABELA AUXILIAR'!$J$5+SUM('SPT-01'!$P$18:$P203))/2,0)*0.9 -> 78466.5 | AD187: 115.8 | AE187: =ROUNDDOWN(('SPT-01'!$M195*'TABELA AUXILIAR'!$J$3+SUM('SPT-01'!$N$10:$N195))/2,0)*0.9 -> 59337 | AF187: =ROUNDDOWN(('SPT-01'!$M195*'TABELA AUXILIAR'!$J$4+SUM('SPT-01'!$O$10:$O195))/2,0)*0.9 -> 64531.8 | AG187: =ROUNDDOWN(('SPT-01'!$M195*'TABELA AUXILIAR'!$J$5+SUM('SPT-01'!$P$10:$P195))/2,0)*0.9 -> 74861.1
O188: 130.8 | P188: =ROUNDDOWN(('SPT-01'!$M220*'TABELA AUXILIAR'!$J$3+SUM('SPT-01'!$N$34:$N220))/2,0)*0.9 -> 67410 | Q188: =ROUNDDOWN(('SPT-01'!$M220*'TABELA AUXILIAR'!$J$4+SUM('SPT-01'!$O$34:$O220))/2,0)*0.9 -> 73302.3 | R188: =ROUNDDOWN(('SPT-01'!$M220*'TABELA AUXILIAR'!$J$5+SUM('SPT-01'!$P$34:$P220))/2,0)*0.9 -> 85011.3 | T188: 126 | U188: =ROUNDDOWN(('SPT-01'!$M212*'TABELA AUXILIAR'!$J$3+SUM('SPT-01'!$N$26:$N212))/2,0)*0.9 -> 65228.4 | V188: =ROUNDDOWN(('SPT-01'!$M212*'TABELA AUXILIAR'!$J$4+SUM('SPT-01'!$O$26:$O212))/2,0)*0.9 -> 70931.7 | W188: =ROUNDDOWN(('SPT-01'!$M212*'TABELA AUXILIAR'!$J$5+SUM('SPT-01'!$P$26:$P212))/2,0)*0.9 -> 82266.3 | Y188: 121.2 | Z188: =ROUNDDOWN(('SPT-01'!$M204*'TABELA AUXILIAR'!$J$3+SUM('SPT-01'!$N$18:$N204))/2,0)*0.9 -> 62662.5 | AA188: =ROUNDDOWN(('SPT-01'!$M204*'TABELA AUXILIAR'!$J$4+SUM('SPT-01'!$O$18:$O204))/2,0)*0.9 -> 68143.5 | AB188: =ROUNDDOWN(('SPT-01'!$M204*'TABELA AUXILIAR'!$J$5+SUM('SPT-01'!$P$18:$P204))/2,0)*0.9 -> 79039.8 | AD188: 116.4 | AE188: =ROUNDDOWN(('SPT-01'!$M196*'TABELA AUXILIAR'!$J$3+SUM('SPT-01'!$N$10:$N196))/2,0)*0.9 -> 59783.4 | AF188: =ROUNDDOWN(('SPT-01'!$M196*'TABELA AUXILIAR'!$J$4+SUM('SPT-01'!$O$10:$O196))/2,0)*0.9 -> 65016.9 | AG188: =ROUNDDOWN(('SPT-01'!$M196*'TABELA AUXILIAR'!$J$5+SUM('SPT-01'!$P$10:$P196))/2,0)*0.9 -> 75421.8
O189: 131.4 | P189: =ROUNDDOWN(('SPT-01'!$M221*'TABELA AUXILIAR'!$J$3+SUM('SPT-01'!$N$34:$N221))/2,0)*0.9 -> 67887.9 | Q189: =ROUNDDOWN(('SPT-01'!$M221*'TABELA AUXILIAR'!$J$4+SUM('SPT-01'!$O$34:$O221))/2,0)*0.9 -> 73820.7 | R189: =ROUNDDOWN(('SPT-01'!$M221*'TABELA AUXILIAR'!$J$5+SUM('SPT-01'!$P$34:$P221))/2,0)*0.9 -> 85610.7 | T189: 126.6 | U189: =ROUNDDOWN(('SPT-01'!$M213*'TABELA AUXILIAR'!$J$3+SUM('SPT-01'!$N$26:$N213))/2,0)*0.9 -> 65696.4 | V189: =ROUNDDOWN(('SPT-01'!$M213*'TABELA AUXILIAR'!$J$4+SUM('SPT-01'!$O$26:$O213))/2,0)*0.9 -> 71439.3 | W189: =ROUNDDOWN(('SPT-01'!$M213*'TABELA AUXILIAR'!$J$5+SUM('SPT-01'!$P$26:$P213))/2,0)*0.9 -> 82853.1 | Y189: 121.8 | Z189: =ROUNDDOWN(('SPT-01'!$M205*'TABELA AUXILIAR'!$J$3+SUM('SPT-01'!$N$18:$N205))/2,0)*0.9 -> 63119.7 | AA189: =ROUNDDOWN(('SPT-01'!$M205*'TABELA AUXILIAR'!$J$4+SUM('SPT-01'!$O$18:$O205))/2,0)*0.9 -> 68641.2 | AB189: =ROUNDDOWN(('SPT-01'!$M205*'TABELA AUXILIAR'!$J$5+SUM('SPT-01'!$P$18:$P205))/2,0)*0.9 -> 79614.9 | AD189: 117 | AE189: =ROUNDDOWN(('SPT-01'!$M197*'TABELA AUXILIAR'!$J$3+SUM('SPT-01'!$N$10:$N197))/2,0)*0.9 -> 60231.6 | AF189: =ROUNDDOWN(('SPT-01'!$M197*'TABELA AUXILIAR'!$J$4+SUM('SPT-01'!$O$10:$O197))/2,0)*0.9 -> 65502.9 | AG189: =ROUNDDOWN(('SPT-01'!$M197*'TABELA AUXILIAR'!$J$5+SUM('SPT-01'!$P$10:$P197))/2,0)*0.9 -> 75984.3
O190: 132 | P190: =ROUNDDOWN(('SPT-01'!$M222*'TABELA AUXILIAR'!$J$3+SUM('SPT-01'!$N$34:$N222))/2,0)*0.9 -> 68366.7 | Q190: =ROUNDDOWN(('SPT-01'!$M222*'TABELA AUXILIAR'!$J$4+SUM('SPT-01'!$O$34:$O222))/2,0)*0.9 -> 74340.9 | R190: =ROUNDDOWN(('SPT-01'!$M222*'TABELA AUXILIAR'!$J$5+SUM('SPT-01'!$P$34:$P222))/2,0)*0.9 -> 86211.9 | T190: 127.2 | U190: =ROUNDDOWN(('SPT-01'!$M214*'TABELA AUXILIAR'!$J$3+SUM('SPT-01'!$N$26:$N214))/2,0)*0.9 -> 66165.3 | V190: =ROUNDDOWN(('SPT-01'!$M214*'TABELA AUXILIAR'!$J$4+SUM('SPT-01'!$O$26:$O214))/2,0)*0.9 -> 71948.7 | W190: =ROUNDDOWN(('SPT-01'!$M214*'TABELA AUXILIAR'!$J$5+SUM('SPT-01'!$P$26:$P214))/2,0)*0.9 -> 83442.6 | Y190: 122.4 | Z190: =ROUNDDOWN(('SPT-01'!$M206*'TABELA AUXILIAR'!$J$3+SUM('SPT-01'!$N$18:$N206))/2,0)*0.9 -> 63578.7 | AA190: =ROUNDDOWN(('SPT-01'!$M206*'TABELA AUXILIAR'!$J$4+SUM('SPT-01'!$O$18:$O206))/2,0)*0.9 -> 69138.9 | AB190: =ROUNDDOWN(('SPT-01'!$M206*'TABELA AUXILIAR'!$J$5+SUM('SPT-01'!$P$18:$P206))/2,0)*0.9 -> 80190.9 | AD190: 117.6 | AE190: =ROUNDDOWN(('SPT-01'!$M198*'TABELA AUXILIAR'!$J$3+SUM('SPT-01'!$N$10:$N198))/2,0)*0.9 -> 60680.7 | AF190: =ROUNDDOWN(('SPT-01'!$M198*'TABELA AUXILIAR'!$J$4+SUM('SPT-01'!$O$10:$O198))/2,0)*0.9 -> 65990.7 | AG190: =ROUNDDOWN(('SPT-01'!$M198*'TABELA AUXILIAR'!$J$5+SUM('SPT-01'!$P$10:$P198))/2,0)*0.9 -> 76547.7
T191: 127.8 | U191: =ROUNDDOWN(('SPT-01'!$M215*'TABELA AUXILIAR'!$J$3+SUM('SPT-01'!$N$26:$N215))/2,0)*0.9 -> 66635.1 | V191: =ROUNDDOWN(('SPT-01'!$M215*'TABELA AUXILIAR'!$J$4+SUM('SPT-01'!$O$26:$O215))/2,0)*0.9 -> 72459 | W191: =ROUNDDOWN(('SPT-01'!$M215*'TABELA AUXILIAR'!$J$5+SUM('SPT-01'!$P$26:$P215))/2,0)*0.9 -> 84033 | Y191: 123 | Z191: =ROUNDDOWN(('SPT-01'!$M207*'TABELA AUXILIAR'!$J$3+SUM('SPT-01'!$N$18:$N207))/2,0)*0.9 -> 64039.5 | AA191: =ROUNDDOWN(('SPT-01'!$M207*'TABELA AUXILIAR'!$J$4+SUM('SPT-01'!$O$18:$O207))/2,0)*0.9 -> 69639.3 | AB191: =ROUNDDOWN(('SPT-01'!$M207*'TABELA AUXILIAR'!$J$5+SUM('SPT-01'!$P$18:$P207))/2,0)*0.9 -> 80768.7 | AD191: 118.2 | AE191: =ROUNDDOWN(('SPT-01'!$M199*'TABELA AUXILIAR'!$J$3+SUM('SPT-01'!$N$10:$N199))/2,0)*0.9 -> 61130.7 | AF191: =ROUNDDOWN(('SPT-01'!$M199*'TABELA AUXILIAR'!$J$4+SUM('SPT-01'!$O$10:$O199))/2,0)*0.9 -> 66479.4 | AG191: =ROUNDDOWN(('SPT-01'!$M199*'TABELA AUXILIAR'!$J$5+SUM('SPT-01'!$P$10:$P199))/2,0)*0.9 -> 77113.8
T192: 128.4 | U192: =ROUNDDOWN(('SPT-01'!$M216*'TABELA AUXILIAR'!$J$3+SUM('SPT-01'!$N$26:$N216))/2,0)*0.9 -> 67106.7 | V192: =ROUNDDOWN(('SPT-01'!$M216*'TABELA AUXILIAR'!$J$4+SUM('SPT-01'!$O$26:$O216))/2,0)*0.9 -> 72971.1 | W192: =ROUNDDOWN(('SPT-01'!$M216*'TABELA AUXILIAR'!$J$5+SUM('SPT-01'!$P$26:$P216))/2,0)*0.9 -> 84624.3 | Y192: 123.6 | Z192: =ROUNDDOWN(('SPT-01'!$M208*'TABELA AUXILIAR'!$J$3+SUM('SPT-01'!$N$18:$N208))/2,0)*0.9 -> 64500.3 | AA192: =ROUNDDOWN(('SPT-01'!$M208*'TABELA AUXILIAR'!$J$4+SUM('SPT-01'!$O$18:$O208))/2,0)*0.9 -> 70140.6 | AB192: =ROUNDDOWN(('SPT-01'!$M208*'TABELA AUXILIAR'!$J$5+SUM('SPT-01'!$P$18:$P208))/2,0)*0.9 -> 81348.3 | AD192: 118.8 | AE192: =ROUNDDOWN(('SPT-01'!$M200*'TABELA AUXILIAR'!$J$3+SUM('SPT-01'!$N$10:$N200))/2,0)*0.9 -> 61581.6 | AF192: =ROUNDDOWN(('SPT-01'!$M200*'TABELA AUXILIAR'!$J$4+SUM('SPT-01'!$O$10:$O200))/2,0)*0.9 -> 66969.9 | AG192: =ROUNDDOWN(('SPT-01'!$M200*'TABELA AUXILIAR'!$J$5+SUM('SPT-01'!$P$10:$P200))/2,0)*0.9 -> 77680.8
T193: 129 | U193: =ROUNDDOWN(('SPT-01'!$M217*'TABELA AUXILIAR'!$J$3+SUM('SPT-01'!$N$26:$N217))/2,0)*0.9 -> 67579.2 | V193: =ROUNDDOWN(('SPT-01'!$M217*'TABELA AUXILIAR'!$J$4+SUM('SPT-01'!$O$26:$O217))/2,0)*0.9 -> 73484.1 | W193: =ROUNDDOWN(('SPT-01'!$M217*'TABELA AUXILIAR'!$J$5+SUM('SPT-01'!$P$26:$P217))/2,0)*0.9 -> 85217.4 | Y193: 124.2 | Z193: =ROUNDDOWN(('SPT-01'!$M209*'TABELA AUXILIAR'!$J$3+SUM('SPT-01'!$N$18:$N209))/2,0)*0.9 -> 64962.9 | AA193: =ROUNDDOWN(('SPT-01'!$M209*'TABELA AUXILIAR'!$J$4+SUM('SPT-01'!$O$18:$O209))/2,0)*0.9 -> 70642.8 | AB193: =ROUNDDOWN(('SPT-01'!$M209*'TABELA AUXILIAR'!$J$5+SUM('SPT-01'!$P$18:$P209))/2,0)*0.9 -> 81929.7 | AD193: 119.4 | AE193: =ROUNDDOWN(('SPT-01'!$M201*'TABELA AUXILIAR'!$J$3+SUM('SPT-01'!$N$10:$N201))/2,0)*0.9 -> 62034.3 | AF193: =ROUNDDOWN(('SPT-01'!$M201*'TABELA AUXILIAR'!$J$4+SUM('SPT-01'!$O$10:$O201))/2,0)*0.9 -> 67461.3 | AG193: =ROUNDDOWN(('SPT-01'!$M201*'TABELA AUXILIAR'!$J$5+SUM('SPT-01'!$P$10:$P201))/2,0)*0.9 -> 78248.7
T194: 129.6 | U194: =ROUNDDOWN(('SPT-01'!$M218*'TABELA AUXILIAR'!$J$3+SUM('SPT-01'!$N$26:$N218))/2,0)*0.9 -> 68052.6 | V194: =ROUNDDOWN(('SPT-01'!$M218*'TABELA AUXILIAR'!$J$4+SUM('SPT-01'!$O$26:$O218))/2,0)*0.9 -> 73998.9 | W194: =ROUNDDOWN(('SPT-01'!$M218*'TABELA AUXILIAR'!$J$5+SUM('SPT-01'!$P$26:$P218))/2,0)*0.9 -> 85812.3 | Y194: 124.8 | Z194: =ROUNDDOWN(('SPT-01'!$M210*'TABELA AUXILIAR'!$J$3+SUM('SPT-01'!$N$18:$N210))/2,0)*0.9 -> 65427.3 | AA194: =ROUNDDOWN(('SPT-01'!$M210*'TABELA AUXILIAR'!$J$4+SUM('SPT-01'!$O$18:$O210))/2,0)*0.9 -> 71146.8 | AB194: =ROUNDDOWN(('SPT-01'!$M210*'TABELA AUXILIAR'!$J$5+SUM('SPT-01'!$P$18:$P210))/2,0)*0.9 -> 82512 | AD194: 120 | AE194: =ROUNDDOWN(('SPT-01'!$M202*'TABELA AUXILIAR'!$J$3+SUM('SPT-01'!$N$10:$N202))/2,0)*0.9 -> 62488.8 | AF194: =ROUNDDOWN(('SPT-01'!$M202*'TABELA AUXILIAR'!$J$4+SUM('SPT-01'!$O$10:$O202))/2,0)*0.9 -> 67954.5 | AG194: =ROUNDDOWN(('SPT-01'!$M202*'TABELA AUXILIAR'!$J$5+SUM('SPT-01'!$P$10:$P202))/2,0)*0.9 -> 78819.3
T195: 130.2 | U195: =ROUNDDOWN(('SPT-01'!$M219*'TABELA AUXILIAR'!$J$3+SUM('SPT-01'!$N$26:$N219))/2,0)*0.9 -> 68527.8 | V195: =ROUNDDOWN(('SPT-01'!$M219*'TABELA AUXILIAR'!$J$4+SUM('SPT-01'!$O$26:$O219))/2,0)*0.9 -> 74514.6 | W195: =ROUNDDOWN(('SPT-01'!$M219*'TABELA AUXILIAR'!$J$5+SUM('SPT-01'!$P$26:$P219))/2,0)*0.9 -> 86409 | Y195: 125.4 | Z195: =ROUNDDOWN(('SPT-01'!$M211*'TABELA AUXILIAR'!$J$3+SUM('SPT-01'!$N$18:$N211))/2,0)*0.9 -> 65892.6 | AA195: =ROUNDDOWN(('SPT-01'!$M211*'TABELA AUXILIAR'!$J$4+SUM('SPT-01'!$O$18:$O211))/2,0)*0.9 -> 71651.7 | AB195: =ROUNDDOWN(('SPT-01'!$M211*'TABELA AUXILIAR'!$J$5+SUM('SPT-01'!$P$18:$P211))/2,0)*0.9 -> 83096.1 | AD195: 120.6 | AE195: =ROUNDDOWN(('SPT-01'!$M203*'TABELA AUXILIAR'!$J$3+SUM('SPT-01'!$N$10:$N203))/2,0)*0.9 -> 62943.3 | AF195: =ROUNDDOWN(('SPT-01'!$M203*'TABELA AUXILIAR'!$J$4+SUM('SPT-01'!$O$10:$O203))/2,0)*0.9 -> 68448.6 | AG195: =ROUNDDOWN(('SPT-01'!$M203*'TABELA AUXILIAR'!$J$5+SUM('SPT-01'!$P$10:$P203))/2,0)*0.9 -> 79390.8
T196: 130.8 | U196: =ROUNDDOWN(('SPT-01'!$M220*'TABELA AUXILIAR'!$J$3+SUM('SPT-01'!$N$26:$N220))/2,0)*0.9 -> 69003.9 | V196: =ROUNDDOWN(('SPT-01'!$M220*'TABELA AUXILIAR'!$J$4+SUM('SPT-01'!$O$26:$O220))/2,0)*0.9 -> 75031.2 | W196: =ROUNDDOWN(('SPT-01'!$M220*'TABELA AUXILIAR'!$J$5+SUM('SPT-01'!$P$26:$P220))/2,0)*0.9 -> 87007.5 | Y196: 126 | Z196: =ROUNDDOWN(('SPT-01'!$M212*'TABELA AUXILIAR'!$J$3+SUM('SPT-01'!$N$18:$N212))/2,0)*0.9 -> 66358.8 | AA196: =ROUNDDOWN(('SPT-01'!$M212*'TABELA AUXILIAR'!$J$4+SUM('SPT-01'!$O$18:$O212))/2,0)*0.9 -> 72158.4 | AB196: =ROUNDDOWN(('SPT-01'!$M212*'TABELA AUXILIAR'!$J$5+SUM('SPT-01'!$P$18:$P212))/2,0)*0.9 -> 83682 | AD196: 121.2 | AE196: =ROUNDDOWN(('SPT-01'!$M204*'TABELA AUXILIAR'!$J$3+SUM('SPT-01'!$N$10:$N204))/2,0)*0.9 -> 63400.5 | AF196: =ROUNDDOWN(('SPT-01'!$M204*'TABELA AUXILIAR'!$J$4+SUM('SPT-01'!$O$10:$O204))/2,0)*0.9 -> 68944.5 | AG196: =ROUNDDOWN(('SPT-01'!$M204*'TABELA AUXILIAR'!$J$5+SUM('SPT-01'!$P$10:$P204))/2,0)*0.9 -> 79964.1
T197: 131.4 | U197: =ROUNDDOWN(('SPT-01'!$M221*'TABELA AUXILIAR'!$J$3+SUM('SPT-01'!$N$26:$N221))/2,0)*0.9 -> 69480.9 | V197: =ROUNDDOWN(('SPT-01'!$M221*'TABELA AUXILIAR'!$J$4+SUM('SPT-01'!$O$26:$O221))/2,0)*0.9 -> 75549.6 | W197: =ROUNDDOWN(('SPT-01'!$M221*'TABELA AUXILIAR'!$J$5+SUM('SPT-01'!$P$26:$P221))/2,0)*0.9 -> 87606.9 | Y197: 126.6 | Z197: =ROUNDDOWN(('SPT-01'!$M213*'TABELA AUXILIAR'!$J$3+SUM('SPT-01'!$N$18:$N213))/2,0)*0.9 -> 66826.8 | AA197: =ROUNDDOWN(('SPT-01'!$M213*'TABELA AUXILIAR'!$J$4+SUM('SPT-01'!$O$18:$O213))/2,0)*0.9 -> 72666 | AB197: =ROUNDDOWN(('SPT-01'!$M213*'TABELA AUXILIAR'!$J$5+SUM('SPT-01'!$P$18:$P213))/2,0)*0.9 -> 84269.7 | AD197: 121.8 | AE197: =ROUNDDOWN(('SPT-01'!$M205*'TABELA AUXILIAR'!$J$3+SUM('SPT-01'!$N$10:$N205))/2,0)*0.9 -> 63857.7 | AF197: =ROUNDDOWN(('SPT-01'!$M205*'TABELA AUXILIAR'!$J$4+SUM('SPT-01'!$O$10:$O205))/2,0)*0.9 -> 69441.3 | AG197: =ROUNDDOWN(('SPT-01'!$M205*'TABELA AUXILIAR'!$J$5+SUM('SPT-01'!$P$10:$P205))/2,0)*0.9 -> 80539.2
T198: 132 | U198: =ROUNDDOWN(('SPT-01'!$M222*'TABELA AUXILIAR'!$J$3+SUM('SPT-01'!$N$26:$N222))/2,0)*0.9 -> 69959.7 | V198: =ROUNDDOWN(('SPT-01'!$M222*'TABELA AUXILIAR'!$J$4+SUM('SPT-01'!$O$26:$O222))/2,0)*0.9 -> 76069.8 | W198: =ROUNDDOWN(('SPT-01'!$M222*'TABELA AUXILIAR'!$J$5+SUM('SPT-01'!$P$26:$P222))/2,0)*0.9 -> 88208.1 | Y198: 127.2 | Z198: =ROUNDDOWN(('SPT-01'!$M214*'TABELA AUXILIAR'!$J$3+SUM('SPT-01'!$N$18:$N214))/2,0)*0.9 -> 67295.7 | AA198: =ROUNDDOWN(('SPT-01'!$M214*'TABELA AUXILIAR'!$J$4+SUM('SPT-01'!$O$18:$O214))/2,0)*0.9 -> 73175.4 | AB198: =ROUNDDOWN(('SPT-01'!$M214*'TABELA AUXILIAR'!$J$5+SUM('SPT-01'!$P$18:$P214))/2,0)*0.9 -> 84858.3 | AD198: 122.4 | AE198: =ROUNDDOWN(('SPT-01'!$M206*'TABELA AUXILIAR'!$J$3+SUM('SPT-01'!$N$10:$N206))/2,0)*0.9 -> 64316.7 | AF198: =ROUNDDOWN(('SPT-01'!$M206*'TABELA AUXILIAR'!$J$4+SUM('SPT-01'!$O$10:$O206))/2,0)*0.9 -> 69939.9 | AG198: =ROUNDDOWN(('SPT-01'!$M206*'TABELA AUXILIAR'!$J$5+SUM('SPT-01'!$P$10:$P206))/2,0)*0.9 -> 81115.2
U199: =ROUNDDOWN(('SPT-01'!$M223*'TABELA AUXILIAR'!$J$3+SUM('SPT-01'!$N$26:$N223))/2,0)*0.9 -> 68085 | V199: =ROUNDDOWN(('SPT-01'!$M223*'TABELA AUXILIAR'!$J$4+SUM('SPT-01'!$O$26:$O223))/2,0)*0.9 -> 73879.2 | W199: =ROUNDDOWN(('SPT-01'!$M223*'TABELA AUXILIAR'!$J$5+SUM('SPT-01'!$P$26:$P223))/2,0)*0.9 -> 85286.7 | Y199: 127.8 | Z199: =ROUNDDOWN(('SPT-01'!$M215*'TABELA AUXILIAR'!$J$3+SUM('SPT-01'!$N$18:$N215))/2,0)*0.9 -> 67765.5 | AA199: =ROUNDDOWN(('SPT-01'!$M215*'TABELA AUXILIAR'!$J$4+SUM('SPT-01'!$O$18:$O215))/2,0)*0.9 -> 73685.7 | AB199: =ROUNDDOWN(('SPT-01'!$M215*'TABELA AUXILIAR'!$J$5+SUM('SPT-01'!$P$18:$P215))/2,0)*0.9 -> 85448.7 | AD199: 123 | AE199: =ROUNDDOWN(('SPT-01'!$M207*'TABELA AUXILIAR'!$J$3+SUM('SPT-01'!$N$10:$N207))/2,0)*0.9 -> 64777.5 | AF199: =ROUNDDOWN(('SPT-01'!$M207*'TABELA AUXILIAR'!$J$4+SUM('SPT-01'!$O$10:$O207))/2,0)*0.9 -> 70439.4 | AG199: =ROUNDDOWN(('SPT-01'!$M207*'TABELA AUXILIAR'!$J$5+SUM('SPT-01'!$P$10:$P207))/2,0)*0.9 -> 81693
U200: =ROUNDDOWN(('SPT-01'!$M224*'TABELA AUXILIAR'!$J$3+SUM('SPT-01'!$N$26:$N224))/2,0)*0.9 -> 68085 | V200: =ROUNDDOWN(('SPT-01'!$M224*'TABELA AUXILIAR'!$J$4+SUM('SPT-01'!$O$26:$O224))/2,0)*0.9 -> 73879.2 | W200: =ROUNDDOWN(('SPT-01'!$M224*'TABELA AUXILIAR'!$J$5+SUM('SPT-01'!$P$26:$P224))/2,0)*0.9 -> 85286.7 | Y200: 128.4 | Z200: =ROUNDDOWN(('SPT-01'!$M216*'TABELA AUXILIAR'!$J$3+SUM('SPT-01'!$N$18:$N216))/2,0)*0.9 -> 68237.1 | AA200: =ROUNDDOWN(('SPT-01'!$M216*'TABELA AUXILIAR'!$J$4+SUM('SPT-01'!$O$18:$O216))/2,0)*0.9 -> 74197.8 | AB200: =ROUNDDOWN(('SPT-01'!$M216*'TABELA AUXILIAR'!$J$5+SUM('SPT-01'!$P$18:$P216))/2,0)*0.9 -> 86040 | AD200: 123.6 | AE200: =ROUNDDOWN(('SPT-01'!$M208*'TABELA AUXILIAR'!$J$3+SUM('SPT-01'!$N$10:$N208))/2,0)*0.9 -> 65238.3 | AF200: =ROUNDDOWN(('SPT-01'!$M208*'TABELA AUXILIAR'!$J$4+SUM('SPT-01'!$O$10:$O208))/2,0)*0.9 -> 70940.7 | AG200: =ROUNDDOWN(('SPT-01'!$M208*'TABELA AUXILIAR'!$J$5+SUM('SPT-01'!$P$10:$P208))/2,0)*0.9 -> 82272.6
